Workbook
Name NamedRange1: 'Bảng giá chi tiết'!$1:$881

Sheet ĐỘC QUYỀN MTS ( SOUTHERN )
A1: HOME PLUS - BẢNG HÀNG ĐỘC QUYỀN DỰ ÁN TRINITY SQUARE - TÒA SOUTHER SQUARE
A2: QUỸ ĐỘC QUYỀN SƠ CẤP S1 (C3L1)
A3: STT | B3: MÃ CĂN | C3: Loại căn | D3: Diện tích thông thủy (m2) | E3: Hướng | F3: CSBH | G3: Ngày KÝ XNDK | H3: Tổng giá chưa VAT & KPBT | I3: Giá tiến độ | J3: Giá TTS | K3: Giá Vay | L3: THƯỞNG SALE | M3: Tình trạng | N3: LINK PTG+ CHỈ CĂN
A4: 1 | B4: C3L1-13-05 | C4: STUDIO | D4: 29, 5 | F4: 45733 | H4: 1,875,428,575
A5: 2 | B5: C3L1-14-19 | C5: STUDIO | D5: 31, 8 | F5: 45733 | H5: 2,107,194,787
A6: 14 | B6: C3L1-04-18A | C6: 2 BR+ | D6: 63 | E6: ĐB | F6: 45733 | G6: 45737 | H6: 3,679,377,723 | I6: 3, 753 | J6: 3, 468 | K6: 3, 997 | N6: https://drive, google, com/drive/folders/1ourAKBlEocXFvtkPLUuyiXakQq7nlGNy
A7: 13 | B7: C3L1-24-15A | C7: 1 BR + 1MR | D7: 58, 1 | E7: TÂY BẮC | F7: 45733 | G7: 45737 | H7: 3,455,608,064 | I7: 3, 526 | J7: 3, 259 | K7: 3, 755 | N7: https://drive, google, com/drive/folders/1tPvxu7FmlyBm7kKhn4B66aHFbnZ1jrWY
A8: 14 | B8: C3L1-10-05A | C8: 2 BR+ | D8: 67, 9 | E8: TB - TN | F8: 45733 | G8: 45737 | H8: 4,112,434,795 | I8: 4, 198 | J8: 3, 879 | K8: 4, 470 | L8: 25TR | N8: https://drive, google, com/drive/folders/1S3p9hl7IPBEWZuH_roevm8U1f7f2NQ8U
A9: 6 | B9: C3L1-05-06 | C9: 1 BR+ | D9: 45, 6 | E9: TÂY BẮC | F9: 45733 | G9: 45737 | H9: 2,672,215,997 | I9: 2, 725 | J9: 2, 519 | K9: 2, 903 | L9: 15TR | N9: https://drive, google, com/drive/folders/1LDrUQVatAG0JaewTQPWT7oeYZzTUtVnX
A10: 1 | B10: C3L1-07-10 | C10: 1 BR | D10: 40 | E10: TÂY BẮC | F10: 45733 | G10: 45742 | H10: 2,453,503,800 | I10: 2, 505 | J10: 2, 315 | K10: 2, 667 | L10: 15TR | N10: https://drive, google, com/drive/folders/1QJ-922fBxDBLSQzQzrFShWFBLJnAD8kG
A11: 2 | B11: C3L1-22-10 | C11: 1 BR | D11: 40 | E11: TÂY BẮC | F11: 45733 | G11: 45737 | H11: 2,481,134,040 | I11: 2, 534 | J11: 2, 342 | K11: 2, 698 | L11: 15TR | N11: https://drive, google, com/drive/folders/1Ym8164pjlcW6ZcaLqOv_zEBqgOSnNcYl
A12: 3 | B12: C3L1-05-22 | C12: 1 BR+ | D12: 47, 3 | E12: ĐÔNG NAM | F12: 45733 | G12: 45737 | H12: 2,878,974,003 | I12: 2, 938 | J12: 2, 716 | K12: 3, 130 | L12: 15TR | M12: đã bán | N12: https://drive, google, com/drive/folders/1JgutseMbOEM-oR0XAUCCmeBxIQK6My4O
A13: 1 | B13: C3L1-08-09 | C13: 1 BR | D13: 40 | E13: TÂY BẮC | F13: 45733 | G13: 45737 | H13: 2, 476, 529, 000 | I13: 2, 529 | J13: 2, 337 | K13: 2, 693 | L13: 15TR | N13: https://drive, google, com/drive/folders/1DnrZEAppl-pMwtOnoaoL-3yPCom_BSea
A14: 0 | B14: C3L1-19-06 | C14: 1 BR+ | D14: 45, 6 | E14: TÂY BẮC | F14: 45733 | G14: 45737 | H14: 2, 897, 955, 012 | L14: 15TR | M14: NHẢ | N14: https://drive, google, com/drive/folders/1Eu0-6kChq3cK4oG3ZXRW0GSlo6Zsy5eX
A15: 0 | B15: C3L1-05-11 | C15: 1 BR + 1MR | D15: 60, 8 | E15: TÂY BẮC | F15: 45733 | G15: 45737 | H15: 3, 426, 412, 640 | L15: 25TR | M15: NHẢ | N15: https://drive, google, com/drive/folders/1j7wmKRuaIXRxwnBtFVxSvXffxV8ovYNv
A16: 0 | B16: C3L1-03-03 | C16: 3 BR | D16: 112, 6 | E16: ĐN -TN | F16: 45733 | G16: 45737 | H16: 6, 231, 579, 800 | L16: 40TR | M16: NHẢ | N16: https://drive, google, com/drive/folders/13otFzdQ1JqNkIKCY6uWedpQHaKjVoPwo
A17: 0 | B17: C3L1-20-20 | C17: 1 BR + 1MR | D17: 61, 4 | E17: ĐÔNG NAM | F17: 45733 | G17: 45745 | H17: 3, 919, 975, 796 | I17: 4, 005 | J17: 3, 702 | K17: 4, 265 | L17: 25TR | M17: ĐÃ BÁN | N17: https://drive, google, com/drive/folders/1ddA0r3Rc2xiORHjWiBGm4OfLaM7YVU-K
A18: 0 | B18: C3L1-13-09 | C18: 1 BR | D18: 40 | E18: TÂY BẮC | F18: 45733 | G18: 45737 | H18: 2, 492, 646, 640 | I18: 2, 546 | J18: 2, 353 | K18: 2, 711 | L18: 15TR | N18: https://drive, google, com/drive/folders/18lrWe3rL_piGyFS4GyRLtxHN-B2YB3Ol
A19: 0 | B19: C3L1-07-03 | C19: 3 BR | D19: 112, 7 | E19: ĐN -TN | F19: 45733 | G19: 45737 | H19: 6, 431, 639, 447 | I19: 6, 558 | J19: 6, 060 | K19: 6, 984 | L19: 40TR | M19: Đã bán | N19: https://drive, google, com/drive/folders/12Zyd654HJAPfpK1tMsBP-0auom8UtuAl
A20: 0 | B20: C3L1-14-15A | C20: 1 BR + 1MR | D20: 58, 1 | E20: TÂY BẮC | F20: 45733 | G20: 45737 | H20: 3, 599, 417, 707 | L20: 25TR | M20: Đã bán
A21: 1 | B21: C3L1-24-08 | C21: 1 BR + 1MR | D21: 58, 8 | E21: TÂY BẮC | F21: 45778 | G21: 45789 | H21: 3, 543, 768, 161 | I21: 3, 674 | J21: 3, 397 | K21: 3, 891 | L21: 25TR | M21: CHECK AD | N21: https://drive, google, com/drive/folders/1PQRObacVx5E8famlJsEoyTAMXWa1sEzh
A22: 1 | B22: C3L1-13-05A | C22: 2 BR+ | D22: 67, 9 | E22: TB - TN | H22: 4, 085, 075, 101 | I22: 4, 245 | J22: 3, 916 | K22: 4, 486 | L22: 25TR | M22: CHECK AD | N22: https://drive, google, com/drive/folders/1cZLLR5mSNRJaqV7EMPMBrEKEzOem4fXF
A23: 1 | B23: C3L1-04-03 | C23: 3 BR | D23: 112, 6 | E23: ĐN-TN | F23: 45778 | G23: 45804 | H23: 6, 296, 395, 738 | I23: 6, 518 | J23: 6, 026 | K23: 6, 905 | L23: 40TR | N23: https://drive, google, com/drive/folders/1zjcw8VWa9DdPofsH2lAfZM1YfSfG5iH3
A24: QUỸ ĐỘC QUYỀN SƠ CẤP S2 (C3L2)
A25: STT | B25: MÃ CĂN | C25: Loại căn | D25: Diện tích thông thủy (m2) | E25: Hướng | F25: CSBH | G25: Ngày KÝ XNDK | H25: Tổng giá chưa VAT & KPBT | I25: Giá tiến độ | J25: Giá TTS | K25: Giá Vay | L25: THƯỞNG SALE | M25: Tình trạng | N25: LINK PTG+ CHỈ CĂN
A26: 20 | B26: C3L2-26-09 | C26: 1 BR | D26: 40 | F26: 45733 | G26: 45737 | H26: 2,414,460,680 | I26: 2, 464 | J26: 2, 277 | K26: 2, 624 | N26: https://drive, google, com/drive/folders/10MX-C9wFgCNQmmyY-yCYWFGMkae8jU77
A27: 21 | B27: C3L2-04-12A | C27: 1 BR | D27: 40 | F27: 45733 | G27: 45737 | H27: 2,324,304,320 | I27: 2, 371 | J27: 2, 191 | K27: 2, 525 | N27: https://drive, google, com/drive/folders/17sqNnEeF_u9WuWjjh07PHJ5hq3m3VSGq
A28: 24 | B28: C3L2-25-06 | C28: 1 BR+ | D28: 45, 7 | F28: 45733 | G28: 45737 | H28: 2,707,966,799 | I28: 2, 763 | J28: 2, 553 | K28: 2, 943 | M28: ĐANG KHÓA | N28: https://drive, google, com/drive/folders/1p3rmdwKj9a9wbzUH6XiaVlFxiNCtrm7e
A29: 17 | B29: C3L2-14-18 | C29: STUDIO | D29: 29, 5 | E29: TÂY NAM | F29: 45733 | H29: 1,916,605,590 | I29: 1, 958 | J29: 1, 810 | K29: 2, 086 | M29: check AD | N29: https://drive, google, com/drive/folders/1dUO_OC2Ee_fMfonuq88-xPOOHGQrX0fK?usp=drive_link
A30: 28 | B30: C3L2-05-20 | C30: 3 BR | D30: 112, 6 | E30: TB - ĐB | F30: 45733 | G30: 45737 | H30: 6,376,458,054 | I30: 6, 500 | J30: 6, 006 | K30: 6, 923 | L30: 40TR | M30: ĐÃ BÁN | N30: https://drive, google, com/drive/folders/1a5v8ea6wBWfu9ZeyuoQDmjARK2tDDdvF
A31: 15 | B31: C3L2-23-15A | C31: 1 BR | D31: 40 | E31: TÂY NAM | F31: 45733 | G31: 45737 | H31: 2,491,093,560 | I31: 2, 544 | J31: 2, 351 | K31: 2, 709 | L31: 15TR | N31: https://drive, google, com/drive/folders/1cY9eGJQ5jFHPty-74c6bGTbzl5nsnm0e
B32: C3L2-18-09 | C32: 1 BR + 1MR | D32: 58, 1 | E32: ĐÔNG NAM | F32: 45733 | G32: 45737 | H32: 3,627,120,310 | I32: 3, 704 | J32: 3, 424 | K32: 3, 945 | L32: 25TR | M32: ĐÃ BÁN | N32: https://drive, google, com/drive/folders/1_6xlJfwq9x_pGtIb4stX0kV3xd5oqzWD
B33: C3L2-20-15A | C33: 1 BR | D33: 40 | E33: TÂY NAM | F33: 45733 | G33: 45737 | H33: 2,556,456,880 | I33: 2, 612 | J33: 2, 414 | K33: 2, 781 | L33: 15TR | M33: ĐÃ BÁN | N33: https://drive, google, com/drive/folders/1qnKvYRbaYMEIr4-Eqrax2VZT5NUf-TJD
B34: C3L2-24-01 | C34: 1 BR+ | D34: 47, 4 | E34: TÂY BẮC | F34: 45733 | G34: 45737 | H34: 2,897,741,362 | I34: 2, 958 | J34: 2, 734 | K34: 3, 150 | L34: 15TR | M34: ĐÃ BÁN | N34: https://drive, google, com/drive/folders/1JUbsbnfb5IO6MXA5OdVfk5H33n-dumRA
A35: 0 | B35: C3L2-10-09 | C35: 1 BR + 1MR | D35: 58, 1 | E35: ĐÔNG NAM | F35: 45733 | G35: 45737 | H35: 3,525,632,450 | I35: 3, 599 | J35: 3, 326 | K35: 3, 833 | L35: 25TR | M35: ĐÃ BÁN | N35: https://drive, google, com/drive/folders/1fyrX-7NOi2z-TAPFiOd2wKnAjyhtctnk
A36: 1 | B36: C3L2-17-01 | C36: 1 BR+ | D36: 47, 4 | E36: TÂY BẮC | F36: 45733 | G36: 45737 | H36: 3,031,285,458 | I36: 3, 097 | J36: 2, 862 | K36: 3, 298 | L36: 15TR | N36: https://drive, google, com/drive/folders/1G9SbK52gl94WTccA8zphPZJMy6Lo6Yfr
A37: 0 | B37: C3L2-13-09 | C37: 1 BR + 1MR | D37: 58, 1 | E37: ĐÔNG NAM | F37: 45733 | G37: 45737 | H37: 3,505,989,654 | I37: 3, 578 | J37: 3, 307 | K37: 3, 811 | L37: 25TR | M37: ĐÃ NHẢ | N37: https://drive, google, com/drive/folders/13sj4VIZhhP6Dv6ubk2k0SEvpKXK3SxPu
A38: 0 | B38: C3L2-19-19 | C38: 2 BR+ | D38: 67, 9 | E38: TB - TN | F38: 45733 | G38: 45737 | H38: 4,303,409,452 | I38: 4, 396 | J38: 4, 063 | K38: 4, 681 | L38: 25TR | M38: ĐÃ NHẢ | N38: https://drive, google, com/drive/folders/16aSko0atSDJpzySp6eaQae8kelR577Nd
A39: 0 | B39: C3L2-05-22 | C39: 1 BR + 1MR | D39: 61 | E39: ĐÔNG BẮC | F39: 45778 | G39: 45789 | H39: 3, 553, 686, 638 | I39: 3, 682 | J39: 3, 404 | K39: 3, 900 | L39: 25TR | M39: Đã bán | N39: https://drive, google, com/drive/folders/1BuZpDXJLwDFjB1axsWOLd4U68HVrIBDr
A40: 0 | B40: C3L2-22-20 | C40: 3 BR | D40: 112, 6 | E40: TB - ĐB | F40: 45733 | G40: 45745 | H40: 6, 807, 501, 723 | I40: 6, 948 | J40: 6, 421 | K40: 7, 399 | L40: 40TR | M40: Đã bán | N40: https://drive, google, com/drive/folders/1wbXJ-7keklf82dlJAwgHDfrBBYqXEBsI
...

Sheet ĐỘC QUYỀN MTS ( CENTRAL - SOUTH
A1: HOME PLUS - BẢNG HÀNG ĐỘC QUYỀN DỰ ÁN TRINITY SQUARE - TÒA CENTRAL SQUARE
A2: QUỸ ĐỘC QUYỀN SƠ CẤP C1 TẦNG 17, 7
A3: STT | B3: MÃ CĂN | C3: Loại căn | D3: Diện tích thông thủy (m2) | E3: Hướng | F3: CSBH | G3: Ngày KÝ XNDK | H3: Tổng giá chưa VAT & KPBT | I3: TỔNG GIÁ FULL | J3: Giá tiến độ | K3: Giá TTS | L3: Giá Vay | M3: Đơn giá (PA TTS) | N3: THƯỞNG SALE | O3: Tình trạng | P3: LINK PTG+ CHỈ CĂN
A4: 0 | B4: C2Z1-17-05 | C4: 2 BR+ | D4: 65, 2 | F4: 45768 | H4: 4,234,214,358 | O4: ĐÃ BÁN
A5: 0 | B5: C2Z1-17-03 | C5: 1 BR | D5: 38, 6 | E5: ĐB | F5: 45768 | H5: 2,591,802,829 | J5: 2649 | K5: 2449 | L5: 2821 | O5: ĐÃ BÁN
B6: C2Z1-17-08A | C6: STUDIO | D6: 29, 4 | F6: 45768 | H6: 1,964,194,096 | I6: 2,166,516,628 | N6: 10TR
B7: C2Z1-17-11 | C7: STUDIO | D7: 30 | F7: 45768 | H7: 2,012,278,200 | I7: 2,219,689,584 | N7: 10TR
B8: C2Z1-17-15 | C8: STUDIO | D8: 30, 7 | F8: 45768 | H8: 2,055,015,296 | I8: 2,266,760,352 | N8: 10TR
A9: 0 | B9: C2Z1-17-02 | C9: 1 BR + 1 MR | D9: 61.6 | E9: ĐB | F9: 45768 | G9: 45782 | H9: 3,954,888,661 | I9: 4,359,534,660 | J9: 4040 | K9: 3734 | L9: 4302 | M9: =LEFT(K9/D9,2)&"tr/m2" -> 60tr/m2 | N9: 25tr | O9: ĐÃ BÁN | P9: https://drive, google, com/drive/folders/1LRnBpyMstD9OQKC3EhDZNjPxFuLaL7mx
A10: 0 | B10: C2Z1-17-05A | C10: 1 BR+ | D10: 45.5 | E10: ĐB | F10: 45768 | G10: 45782 | H10: 2,968,294,602 | I10: 3,272,829,254 | J10: 3033 | K10: 2803 | L10: 3230 | M10: =LEFT(K10/D10,2)&"tr/m2" -> 61tr/m2 | N10: 15tr | O10: ĐÃ BÁN | P10: https://drive, google, com/drive/folders/1zS0dBsznpyqWkePsBoWQYhcdEOuJm4Ed
A11: 0 | B11: C2Z1-17-18 | C11: 1 BR+ | D11: 46.8 | E11: ĐB | F11: 45768 | G11: 45782 | H11: 3,057,113,686 | I11: 3,370,830,609 | J11: 3124 | K11: 2887 | L11: 3326 | M11: =LEFT(K11/D11,2)&"tr/m2" -> 61tr/m2 | N11: 15tr | O11: Đã bán | P11: https://drive, google, com/drive/folders/11FCXeSYbCT8CB3VbWk_0COvuVyZQcQgx
A12: 1 | B12: C2Z1-17-19 | C12: 1 BR + 1 MR | D12: 60.3 | E12: ĐB | H12: 3,872,930,792 | I12: 4,269,217,867 | J12: 3956 | K12: 3656 | L12: 4213 | M12: =LEFT(K12/D12,2)&"tr/m2" -> 60tr/m2 | N12: 25tr | O12: CHECK AD | P12: https://drive, google, com/drive/folders/1t0LxNViE5gorDeLfd4hi_ZBK4j7Cv9oo
A13: 0 | B13: C2Z1-17-08 | C13: 1 BR+ | D13: 45.6 | E13: TN | F13: 45768 | G13: 45834 | H13: 2,945,938,022 | I13: 3,247,676,344 | J13: 3009 | K13: 2781 | L13: 3205 | M13: =LEFT(K13/D13,2)&"tr/m2" -> 60tr/m2 | N13: 15tr | O13: ĐÃ BÁN | P13: https://drive, google, com/drive/folders/1kwMZnyEnL8j_hJutD9r-lKo9J1k_iPtB
A14: 5 | B14: C2Z1-17-09 | C14: 1 BR + 1 MR | D14: 59.5 | E14: TN | H14: 3,764,467,480 | I14: 4,148,647,278 | N14: 25tr | O14: check ad | P14: https://drive, google, com/drive/folders/175dOLg1CYPOYpCnuctV6pyYkxg31HNbY
A15: 7 | B15: C2Z1-17-16 | C15: 2 BR+ | D15: 65.5 | E15: TN-TB | H15: 4,212,035,075 | I15: 4,643,110,585 | N15: 25tr | O15: check ad | P15: https://drive, google, com/drive/folders/1fOCH76AHE1WwWHB3QpuCtvHqd05wsVm0
A16: 8 | B16: C2Z1-17-10 | C16: 1 BR + 1 MR | D16: 59.8 | E16: TN | H16: 3,920,312,427 | I16: 4,322,852,999 | N16: 25tr | O16: check ad | P16: https://drive, google, com/drive/folders/1l-ohTmKtdvmD8_WDt_JOeKn5p8Jqejlf
A17: 10 | B17: C2Z1-17-18A | C17: 2 BR + 1 MR | D17: 100.1 | E17: TB-ĐB | H17: 6,302,925,028 | I17: 6,945,622,492 | N17: 25tr | O17: check ad | P17: https://drive, google, com/drive/folders/1SCRuLwR2HZGNQ8Sf0gZ_A51bCA-AWNRb
A18: 3 | B18: C2Z1-17-12A | C18: 1 BR+ | D18: 45.7 | E18: TN | F18: 45768 | G18: 45782 | H18: 2,910,346,644 | I18: 3,207,700,461 | J18: 2972 | K18: 2747 | L18: 3165 | M18: =LEFT(K18/D18,2)&"tr/m2" -> 60tr/m2 | N18: 15tr | O18: ĐÃ BÁN | P18: https://drive, google, com/drive/folders/1RTz0Nm2YxvbIvhGwrk1u6KZe1jOIVi17
A19: 4 | B19: C2Z1-17-15A | C19: 1 BR | D19: 40.8 | E19: TN | F19: 45768 | G19: 45782 | H19: 2,715,745,716 | I19: 2,995,310,882 | J19: 2776 | K19: 2565 | L19: 2956 | M19: =LEFT(K19/D19,2)&"tr/m2" -> 62tr/m2 | N19: 15tr | O19: ĐÃ BÁN | P19: https://drive, google, com/drive/folders/1Fht5b474d2ypJepMkNjlnRy284TWIgy5
A20: 3 | B20: C2Z1-17-06 | C20: 2 BR+ | D20: 65.2 | E20: ĐN-TN | F20: 45768 | G20: 45838 | H20: 4,174,368,060 | I20: 4,601,264,147 | J20: 4264 | K20: 3941 | L20: 4541 | M20: =LEFT(K20/D20,2)&"tr/m2" -> 60tr/m2 | N20: 25tr | O20: đã bán | P20: https://drive, google, com/drive/folders/1jL_Xjswvxy-6P_-yGb0rCVx-axcGclLH
A21: 1 | B21: C2Z1-13-12 | C21: 1 BR+ | D21: 45.7 | E21: TN | F21: 45768 | G21: 45834 | H21: 2852668902 | I21: 3143101390 | J21: 2912 | K21: 2692 | L21: 3102 | M21: =LEFT(K21/D21,2)&"tr/m2" -> 58tr/m2 | N21: 15tr | O21: Đã bán | P21: https://drive, google, com/drive/folders/19XvXvnMM4DvIvv6GaDo3NESLWaVjJ4jf
A22: 2 | B22: C2Z1-17-12 | C22: 1 BR+ | D22: 45.7 | E22: TN | F22: 45768 | G22: 45782 | H22: 2,936,563,820 | I22: 3,237,063,698 | J22: 2999 | K22: 2772 | L22: 3194 | M22: =LEFT(K22/D22,2)&"tr/m2" -> 60tr/m2 | N22: 15tr | O22: Đã bán | P22: https://drive, google, com/drive/folders/1d3RhTlAM3j7efsttuuLh0ShoxTY-UBLd
A23: 1 | B23: C2Z1-17-01 | C23: 2 BR + 1 MR | D23: 103 | E23: TB-ĐB | F23: 45768 | G23: 45838 | H23: 6,423,337,603 | I23: 7,077,191,915 | J23: 6558 | K23: 6061 | L23: 6984 | M23: =LEFT(K23/D23,2)&"tr/m2" -> 58tr/m2 | N23: 25tr | P23: https://drive, google, com/drive/folders/1Hlj886kTj3fRmj1Un5W5018EUzovqWm_
A24: QUỸ ĐỘC QUYỀN SƠ CẤP C1 TẦNG 7
A25: STT | B25: MÃ CĂN | C25: Loại căn | D25: Diện tích thông thủy (m2) | E25: Hướng | F25: CSBH | G25: Ngày KÝ XNDK | H25: Tổng giá chưa VAT & KPBT | I25: TỔNG GIÁ FULL | J25: Giá tiến độ | K25: Giá TTS | L25: Giá Vay | M25: Đơn giá (PA TTS) | N25: THƯỞNG SALE | O25: Tình trạng | P25: LINK PTG+ CHỈ CĂN
A26: 0 | B26: C2Z1-07-03 | C26: 1 BR | D26: 38.6 | E26: ĐB | F26: 45768 | H26: 2,478,868,261 | I26: 2,732,506,012 | J26: 2532 | K26: 2340 | L26: 2696 | M26: =LEFT(K26/D26,2)&"tr/m2" -> 60tr/m2 | N26: 15tr | O26: ĐÃ BÁN | P26: https://drive, google, com/drive/folders/1XU0sQCw_1TGS9RQKuQpF8u-EHHOGuQj7
A27: 0 | B27: C2Z1-07-05A | C27: 1 BR+ | D27: 45.5 | E27: ĐB | F27: 45768 | H27: 2,835,172,204 | I27: 3,123,732,168 | J27: 2894 | K27: 2675 | L27: 3082 | M27: =LEFT(K27/D27,2)&"tr/m2" -> 58tr/m2 | N27: 15tr | O27: ĐÃ BÁN | P27: https://drive, google, com/drive/folders/1KtUFMXB0Q_Srru9NL66mshyzQaeRJ50w
A28: 0 | B28: C2Z1-07-18 | C28: 1 BR+ | D28: 46.8 | E28: ĐB | F28: 45768 | G28: 45787 | H28: 2,920,187,790 | I28: 3,217,473,605 | J28: 2981 | K28: 2755 | L28: 3175 | M28: =LEFT(K28/D28,2)&"tr/m2" -> 58tr/m2 | N28: 15tr | O28: Đã bán | P28: https://drive, google, com/drive/folders/1A4kfQWs1-YXZilUO9fdwEhfFWe0AAnpP
A29: 0 | B29: C2Z1-07-05 | C29: 2 BR+ | D29: 65.2 | E29: ĐB-ĐN | F29: 45768 | G29: 45787 | H29: 4,043,454,349 | I29: 4,454,640,791 | J29: 4128 | K29: 3815 | L29: 4396 | M29: =LEFT(K29/D29,2)&"tr/m2" -> 58tr/m2 | N29: 25tr | O29: Đã bán | P29: https://drive, google, com/drive/folders/1ozwB7lDTP68qWVKjF2OwAod4R6ZTupXr
A30: 0 | B30: C2Z1-07-12 | C30: 1 BR+ | D30: 45.7 | E30: TN | F30: 45768 | G30: 45787 | H30: 2,787,125,962 | I30: 3,069,693,297 | J30: 2844 | K30: 2629 | L30: 3029 | M30: =LEFT(K30/D30,2)&"tr/m2" -> 57tr/m2 | N30: 15tr | O30: Đã bán | P30: https://drive, google, com/drive/folders/1W5h2vNByzLoGR2kBtkLCh8vxGjJDXN_D
A31: 0 | B31: C2Z1-07-12A | C31: 1 BR+ | D31: 45.7 | E31: TN | F31: 45768 | G31: 45787 | H31: 2,760,908,786 | I31: 3,040,330,061 | J31: 2817 | K31: 2603 | L31: 3000 | M31: =LEFT(K31/D31,2)&"tr/m2" -> 56tr/m2 | N31: 15tr | O31: Đã bán | P31: https://drive, google, com/drive/folders/10p96RBQE7H_4yv2OsQkEbCxABLjPSeju
A32: 0 | B32: C2Z1-07-08 | C32: 1 BR+ | D32: 45.6 | E32: TN | F32: 45768 | G32: 45787 | H32: 2,796,827,162 | I32: 3,080,672,181 | J32: 2855 | K32: 2638 | L32: 3040 | M32: =LEFT(K32/D32,2)&"tr/m2" -> 57tr/m2 | N32: 15tr | O32: Đã bán | P32: https://drive, google, com/drive/folders/1CTmCZb0Z6OMEeVLTo7r1QFSd-KgBO3QQ
A33: 1 | B33: C2Z1-07-15A | C33: 1 BR | D33: 40.8 | E33: TN | F33: 45768 | G33: 45787 | H33: 2,582,330,736 | I33: 2,845,886,105 | J33: 2637 | K33: 2437 | L33: 2808 | M33: =LEFT(K33/D33,2)&"tr/m2" -> 59tr/m2 | N33: 15tr | O33: đã bán | P33: https://drive, google, com/drive/folders/1mUAKNpphol3ZbmaqVLRX_SO5-KbaID_7
A34: 1 | B34: C2Z1-07-02 | C34: 1 BR + 1 MR | D34: 61.6 | E34: ĐB | F34: 45768 | G34: 45787 | H34: 3,774,661,414 | I34: 4,157,680,143 | J34: 3852 | K34: 3560 | L34: 4103 | M34: =LEFT(K34/D34,2)&"tr/m2" -> 57tr/m2 | N34: 25tr | O34: Đã bán | P34: https://drive, google, com/drive/folders/1uTJv6V93ivV19Oekv0XFaPNtu-XWU8KB
A35: 3 | B35: C2Z1-07-19 | C35: 1 BR + 1 MR | D35: 60.3 | E35: ĐB | F35: 45768 | G35: 45838 | H35: 3,696,507,103 | I35: 4,071,623,335 | J35: 3772 | K35: 3487 | L35: 4018 | M35: =LEFT(K35/D35,2)&"tr/m2" -> 57tr/m2 | N35: 25tr | O35: Đã bán | P35: https://drive, google, com/drive/folders/1cKrWEprokDLj5tzlAuh4FX0MIzSrgiPW
A36: 6 | B36: C2Z1-07-10 | C36: 1 BR + 1 MR | D36: 59.8 | E36: TN | H36: 3,724,767,982 | I36: 4,103,843,220 | J36: 3803 | K36: 3514 | L36: 4050 | M36: =LEFT(K36/D36,2)&"tr/m2" -> 58tr/m2 | N36: 25tr | O36: CHECK AD
A37: 7 | B37: C2Z1-07-01 | C37: 2 BR + 1 MR | D37: 103 | E37: TB-ĐB | H37: 6,092,439,185 | I37: 6,706,585,688 | J37: 6214 | K37: 5742 | L37: 6618 | M37: =LEFT(K37/D37,2)&"tr/m2" -> 55tr/m2 | N37: 25tr | O37: CHECK AD
A38: 8 | B38: C2Z1-07-18A | C38: 2 BR + 1 MR | D38: 100.1 | E38: TB-ĐB | H38: 5,981,343,068 | I38: 6,585,450,696 | J38: 6102 | K38: 5639 | L38: 6499 | M38: =LEFT(K38/D38,2)&"tr/m2" -> 56tr/m2 | N38: 25tr | O38: CHECK AD
A39: 2 | B39: C2Z1-07-06 | C39: 2 BR+ | D39: 65.2 | E39: ĐN-TN | F39: 45768 | G39: 45834 | H39: 3,961,165,690 | I39: 4,362,477,493 | J39: 4042 | K39: 3736 | L39: 4305 | M39: =LEFT(K39/D39,2)&"tr/m2" -> 57tr/m2 | N39: 25tr | O39: đã bán | P39: https://drive, google, com/drive/folders/1h9zrprqEjBrnFjTFuryFxJwWrxNJI84q
A40: 3 | B40: C2Z1-07-16 | C40: 2 BR+ | D40: 65.5 | E40: TN-TB | F40: 45768 | G40: 45838 | H40: 3,997,851,712 | I40: 4,403,225,217 | J40: 4080 | K40: 3771 | L40: 4345 | M40: =LEFT(K40/D40,2)&"tr/m2" -> 57tr/m2 | N40: 25tr | O40: Đã bán | P40: https://drive, google, com/drive/folders/1cV8AJNc6EBZiGU8VMsDArWV2GmghioXA
...

Sheet C1-CT
D1: CẬP NHẬT BẢNG HÀNG TÒA C1 - PHÂN KHU CENTRAL SQUARE
A2: C2Z1- | D2: Ngày cập nhật: | G2: =today() -> 46212 | L2: Quỹ chung | N2: Độc quyền | P2: Đã bán | R2: Quỹ CHECK AD
A4: TẦNG/CĂN | B4: -01 | C4: -02 | D4: -03 | E4: -05A | F4: -05 | G4: -06 | H4: -08A | I4: -08 | J4: -09 | K4: -10 | L4: -11 | M4: -12 | N4: -12A | O4: -15A | P4: -15 | Q4: -16 | R4: -18A | S4: -18 | T4: -19 | U4: TẦNG/CĂN
A5: Loại căn | B5: 2BR + 1MR | C5: 1 BR + 1MR | D5: 1 BR | E5: 1 BR+ | F5: 2 BR+ | G5: 2 BR+ | H5: Studio | I5: 1 BR+ | J5: 1 BR + 1MR | K5: 1 BR + 1MR | L5: Studio | M5: 1 BR+ | N5: 1 BR+ | O5: 1 BR | P5: Studio | Q5: 2 BR+ | R5: 2BR + 1MR | S5: 1 BR+ | T5: 1 BR + 1MR | U5: Loại căn
A6: DT TT | B6: 103 | C6: 61,6 | D6: 38,6 | E6: 45,5 | F6: 65,2 | G6: 65,2 | H6: 29,4 | I6: 45,6 | J6: 59,5 | K6: 59,8 | L6: 30 | M6: 45,7 | N6: 45,7 | O6: 40,8 | P6: 30,7 | Q6: 65,5 | R6: 100,1 | S6: 46,8 | T6: 60,3 | U6: DT TT
A7: Hướng ban công | B7: TB - ĐB | C7: ĐB | D7: ĐB | E7: ĐB | F7: ĐB - ĐN | G7: ĐN - TN | H7: TN | I7: TN | J7: TN | K7: TN | L7: TN | M7: TN | N7: TN | O7: TN | P7: TN | Q7: TN - TB | R7: TB - ĐB | S7: ĐB | T7: ĐB | U7: Hướng ban công
A8: View | B8: View Nội khu - Công viên | G8: View Biệt thự thấp tầng, đường lớn | R8: View Nội khu - Công viên | U8: View
A9: 01 | B9: =IFERROR(VLOOKUP($A$2&$A9&B$4,'Bảng giá chi tiết'!$C:$J,8,0),"") | C9: =IFERROR(VLOOKUP($A$2&$A9&C$4,'Bảng giá chi tiết'!$C:$J,8,0),"") | D9: =IFERROR(VLOOKUP($A$2&$A9&D$4,'Bảng giá chi tiết'!$C:$J,8,0),"") | E9: =IFERROR(VLOOKUP($A$2&$A9&E$4,'Bảng giá chi tiết'!$C:$J,8,0),"") | F9: =IFERROR(VLOOKUP($A$2&$A9&F$4,'Bảng giá chi tiết'!$C:$J,8,0),"") | G9: =IFERROR(VLOOKUP($A$2&$A9&G$4,'Bảng giá chi tiết'!$C:$J,8,0),"") | H9: =IFERROR(VLOOKUP($A$2&$A9&H$4,'Bảng giá chi tiết'!$C:$J,8,0),"") | I9: =IFERROR(VLOOKUP($A$2&$A9&I$4,'Bảng giá chi tiết'!$C:$J,8,0),"") | ... T9: =IFERROR(VLOOKUP($A$2&$A9&T$4,'Bảng giá chi tiết'!$C:$J,8,0),"") | U9: 01
A10: 02 | B10: =IFERROR(VLOOKUP($A$2&$A10&B$4,'Bảng giá chi tiết'!$C:$J,8,0),"") | C10: =IFERROR(VLOOKUP($A$2&$A10&C$4,'Bảng giá chi tiết'!$C:$J,8,0),"") | D10: =IFERROR(VLOOKUP($A$2&$A10&D$4,'Bảng giá chi tiết'!$C:$J,8,0),"") | E10: =IFERROR(VLOOKUP($A$2&$A10&E$4,'Bảng giá chi tiết'!$C:$J,8,0),"") | F10: =IFERROR(VLOOKUP($A$2&$A10&F$4,'Bảng giá chi tiết'!$C:$J,8,0),"") | G10: =IFERROR(VLOOKUP($A$2&$A10&G$4,'Bảng giá chi tiết'!$C:$J,8,0),"") | H10: =IFERROR(VLOOKUP($A$2&$A10&H$4,'Bảng giá chi tiết'!$C:$J,8,0),"") | I10: =IFERROR(VLOOKUP($A$2&$A10&I$4,'Bảng giá chi tiết'!$C:$J,8,0),"") | ... T10: =IFERROR(VLOOKUP($A$2&$A10&T$4,'Bảng giá chi tiết'!$C:$J,8,0),"") | U10: 02
A11: 03 | B11: =IFERROR(VLOOKUP($A$2&$A11&B$4,'Bảng giá chi tiết'!$C:$J,8,0),"") | C11: =IFERROR(VLOOKUP($A$2&$A11&C$4,'Bảng giá chi tiết'!$C:$J,8,0),"") | D11: =IFERROR(VLOOKUP($A$2&$A11&D$4,'Bảng giá chi tiết'!$C:$J,8,0),"") | E11: =IFERROR(VLOOKUP($A$2&$A11&E$4,'Bảng giá chi tiết'!$C:$J,8,0),"") | F11: =IFERROR(VLOOKUP($A$2&$A11&F$4,'Bảng giá chi tiết'!$C:$J,8,0),"") | G11: =IFERROR(VLOOKUP($A$2&$A11&G$4,'Bảng giá chi tiết'!$C:$J,8,0),"") | H11: =IFERROR(VLOOKUP($A$2&$A11&H$4,'Bảng giá chi tiết'!$C:$J,8,0),"") | I11: =IFERROR(VLOOKUP($A$2&$A11&I$4,'Bảng giá chi tiết'!$C:$J,8,0),"") | ... T11: =IFERROR(VLOOKUP($A$2&$A11&T$4,'Bảng giá chi tiết'!$C:$J,8,0),"") | U11: 03
A12: 04 | B12: =IFERROR(VLOOKUP($A$2&$A12&B$4,'Bảng giá chi tiết'!$C:$J,8,0),"") | C12: =IFERROR(VLOOKUP($A$2&$A12&C$4,'Bảng giá chi tiết'!$C:$J,8,0),"") | D12: =IFERROR(VLOOKUP($A$2&$A12&D$4,'Bảng giá chi tiết'!$C:$J,8,0),"") | E12: =IFERROR(VLOOKUP($A$2&$A12&E$4,'Bảng giá chi tiết'!$C:$J,8,0),"") | F12: =IFERROR(VLOOKUP($A$2&$A12&F$4,'Bảng giá chi tiết'!$C:$J,8,0),"") | G12: =IFERROR(VLOOKUP($A$2&$A12&G$4,'Bảng giá chi tiết'!$C:$J,8,0),"") | H12: =IFERROR(VLOOKUP($A$2&$A12&H$4,'Bảng giá chi tiết'!$C:$J,8,0),"") | I12: =IFERROR(VLOOKUP($A$2&$A12&I$4,'Bảng giá chi tiết'!$C:$J,8,0),"") | ... T12: =IFERROR(VLOOKUP($A$2&$A12&T$4,'Bảng giá chi tiết'!$C:$J,8,0),"") | U12: 04
A13: 05 | B13: =IFERROR(VLOOKUP($A$2&$A13&B$4,'Bảng giá chi tiết'!$C:$J,8,0),"") -> 0? | C13: =IFERROR(VLOOKUP($A$2&$A13&C$4,'Bảng giá chi tiết'!$C:$J,8,0),"") | D13: =IFERROR(VLOOKUP($A$2&$A13&D$4,'Bảng giá chi tiết'!$C:$J,8,0),"") | E13: =IFERROR(VLOOKUP($A$2&$A13&E$4,'Bảng giá chi tiết'!$C:$J,8,0),"") | F13: =IFERROR(VLOOKUP($A$2&$A13&F$4,'Bảng giá chi tiết'!$C:$J,8,0),"") -> 0? | G13: =IFERROR(VLOOKUP($A$2&$A13&G$4,'Bảng giá chi tiết'!$C:$J,8,0),"") | H13: =IFERROR(VLOOKUP($A$2&$A13&H$4,'Bảng giá chi tiết'!$C:$J,8,0),"") | I13: =IFERROR(VLOOKUP($A$2&$A13&I$4,'Bảng giá chi tiết'!$C:$J,8,0),"") | ... T13: =IFERROR(VLOOKUP($A$2&$A13&T$4,'Bảng giá chi tiết'!$C:$J,8,0),"") | U13: 05
A14: 06 | B14: =IFERROR(VLOOKUP($A$2&$A14&B$4,'Bảng giá chi tiết'!$C:$J,8,0),"") | C14: =IFERROR(VLOOKUP($A$2&$A14&C$4,'Bảng giá chi tiết'!$C:$J,8,0),"") | D14: =IFERROR(VLOOKUP($A$2&$A14&D$4,'Bảng giá chi tiết'!$C:$J,8,0),"") | E14: =IFERROR(VLOOKUP($A$2&$A14&E$4,'Bảng giá chi tiết'!$C:$J,8,0),"") | F14: =IFERROR(VLOOKUP($A$2&$A14&F$4,'Bảng giá chi tiết'!$C:$J,8,0),"") | G14: =IFERROR(VLOOKUP($A$2&$A14&G$4,'Bảng giá chi tiết'!$C:$J,8,0),"") | H14: =IFERROR(VLOOKUP($A$2&$A14&H$4,'Bảng giá chi tiết'!$C:$J,8,0),"") | I14: =IFERROR(VLOOKUP($A$2&$A14&I$4,'Bảng giá chi tiết'!$C:$J,8,0),"") | ... T14: =IFERROR(VLOOKUP($A$2&$A14&T$4,'Bảng giá chi tiết'!$C:$J,8,0),"") | U14: 06
A15: 07 | B15: =IFERROR(VLOOKUP($A$2&$A15&B$4,'Bảng giá chi tiết'!$C:$J,8,0),"") | C15: =IFERROR(VLOOKUP($A$2&$A15&C$4,'Bảng giá chi tiết'!$C:$J,8,0),"") | D15: =IFERROR(VLOOKUP($A$2&$A15&D$4,'Bảng giá chi tiết'!$C:$J,8,0),"") | E15: =IFERROR(VLOOKUP($A$2&$A15&E$4,'Bảng giá chi tiết'!$C:$J,8,0),"") | F15: =IFERROR(VLOOKUP($A$2&$A15&F$4,'Bảng giá chi tiết'!$C:$J,8,0),"") -> 0? | G15: =IFERROR(VLOOKUP($A$2&$A15&G$4,'Bảng giá chi tiết'!$C:$J,8,0),"") | H15: =IFERROR(VLOOKUP($A$2&$A15&H$4,'Bảng giá chi tiết'!$C:$J,8,0),"") | I15: =IFERROR(VLOOKUP($A$2&$A15&I$4,'Bảng giá chi tiết'!$C:$J,8,0),"") | ... T15: =IFERROR(VLOOKUP($A$2&$A15&T$4,'Bảng giá chi tiết'!$C:$J,8,0),"") | U15: 07
A16: 08 | B16: =IFERROR(VLOOKUP($A$2&$A16&B$4,'Bảng giá chi tiết'!$C:$J,8,0),"") | C16: =IFERROR(VLOOKUP($A$2&$A16&C$4,'Bảng giá chi tiết'!$C:$J,8,0),"") | D16: =IFERROR(VLOOKUP($A$2&$A16&D$4,'Bảng giá chi tiết'!$C:$J,8,0),"") | E16: =IFERROR(VLOOKUP($A$2&$A16&E$4,'Bảng giá chi tiết'!$C:$J,8,0),"") | F16: =IFERROR(VLOOKUP($A$2&$A16&F$4,'Bảng giá chi tiết'!$C:$J,8,0),"") | G16: =IFERROR(VLOOKUP($A$2&$A16&G$4,'Bảng giá chi tiết'!$C:$J,8,0),"") | H16: =IFERROR(VLOOKUP($A$2&$A16&H$4,'Bảng giá chi tiết'!$C:$J,8,0),"") | I16: =IFERROR(VLOOKUP($A$2&$A16&I$4,'Bảng giá chi tiết'!$C:$J,8,0),"") | ... T16: =IFERROR(VLOOKUP($A$2&$A16&T$4,'Bảng giá chi tiết'!$C:$J,8,0),"") | U16: 08
A17: 09 | B17: =IFERROR(VLOOKUP($A$2&$A17&B$4,'Bảng giá chi tiết'!$C:$J,8,0),"") | C17: =IFERROR(VLOOKUP($A$2&$A17&C$4,'Bảng giá chi tiết'!$C:$J,8,0),"") | D17: =IFERROR(VLOOKUP($A$2&$A17&D$4,'Bảng giá chi tiết'!$C:$J,8,0),"") | E17: =IFERROR(VLOOKUP($A$2&$A17&E$4,'Bảng giá chi tiết'!$C:$J,8,0),"") | F17: =IFERROR(VLOOKUP($A$2&$A17&F$4,'Bảng giá chi tiết'!$C:$J,8,0),"") | G17: =IFERROR(VLOOKUP($A$2&$A17&G$4,'Bảng giá chi tiết'!$C:$J,8,0),"") | H17: =IFERROR(VLOOKUP($A$2&$A17&H$4,'Bảng giá chi tiết'!$C:$J,8,0),"") | I17: =IFERROR(VLOOKUP($A$2&$A17&I$4,'Bảng giá chi tiết'!$C:$J,8,0),"") | ... T17: =IFERROR(VLOOKUP($A$2&$A17&T$4,'Bảng giá chi tiết'!$C:$J,8,0),"") | U17: 09
A18: 10 | B18: =IFERROR(VLOOKUP($A$2&$A18&B$4,'Bảng giá chi tiết'!$C:$J,8,0),"") | C18: =IFERROR(VLOOKUP($A$2&$A18&C$4,'Bảng giá chi tiết'!$C:$J,8,0),"") -> 0? | D18: =IFERROR(VLOOKUP($A$2&$A18&D$4,'Bảng giá chi tiết'!$C:$J,8,0),"") -> 0? | E18: =IFERROR(VLOOKUP($A$2&$A18&E$4,'Bảng giá chi tiết'!$C:$J,8,0),"") | F18: =IFERROR(VLOOKUP($A$2&$A18&F$4,'Bảng giá chi tiết'!$C:$J,8,0),"") | G18: =IFERROR(VLOOKUP($A$2&$A18&G$4,'Bảng giá chi tiết'!$C:$J,8,0),"") | H18: =IFERROR(VLOOKUP($A$2&$A18&H$4,'Bảng giá chi tiết'!$C:$J,8,0),"") | I18: =IFERROR(VLOOKUP($A$2&$A18&I$4,'Bảng giá chi tiết'!$C:$J,8,0),"") | ... T18: =IFERROR(VLOOKUP($A$2&$A18&T$4,'Bảng giá chi tiết'!$C:$J,8,0),"") -> 0? | U18: 10
A19: 11 | B19: =IFERROR(VLOOKUP($A$2&$A19&B$4,'Bảng giá chi tiết'!$C:$J,8,0),"") -> 5025? | C19: =IFERROR(VLOOKUP($A$2&$A19&C$4,'Bảng giá chi tiết'!$C:$J,8,0),"") -> 4343? | D19: =IFERROR(VLOOKUP($A$2&$A19&D$4,'Bảng giá chi tiết'!$C:$J,8,0),"") | E19: =IFERROR(VLOOKUP($A$2&$A19&E$4,'Bảng giá chi tiết'!$C:$J,8,0),"") | F19: =IFERROR(VLOOKUP($A$2&$A19&F$4,'Bảng giá chi tiết'!$C:$J,8,0),"") -> 6354? | G19: =IFERROR(VLOOKUP($A$2&$A19&G$4,'Bảng giá chi tiết'!$C:$J,8,0),"") | H19: =IFERROR(VLOOKUP($A$2&$A19&H$4,'Bảng giá chi tiết'!$C:$J,8,0),"") | I19: =IFERROR(VLOOKUP($A$2&$A19&I$4,'Bảng giá chi tiết'!$C:$J,8,0),"") | ... T19: =IFERROR(VLOOKUP($A$2&$A19&T$4,'Bảng giá chi tiết'!$C:$J,8,0),"") -> 4314? | U19: 11
A20: 12 | B20: =IFERROR(VLOOKUP($A$2&$A20&B$4,'Bảng giá chi tiết'!$C:$J,8,0),"") | C20: =IFERROR(VLOOKUP($A$2&$A20&C$4,'Bảng giá chi tiết'!$C:$J,8,0),"") | D20: =IFERROR(VLOOKUP($A$2&$A20&D$4,'Bảng giá chi tiết'!$C:$J,8,0),"") | E20: =IFERROR(VLOOKUP($A$2&$A20&E$4,'Bảng giá chi tiết'!$C:$J,8,0),"") | F20: =IFERROR(VLOOKUP($A$2&$A20&F$4,'Bảng giá chi tiết'!$C:$J,8,0),"") | G20: =IFERROR(VLOOKUP($A$2&$A20&G$4,'Bảng giá chi tiết'!$C:$J,8,0),"") | H20: =IFERROR(VLOOKUP($A$2&$A20&H$4,'Bảng giá chi tiết'!$C:$J,8,0),"") | I20: =IFERROR(VLOOKUP($A$2&$A20&I$4,'Bảng giá chi tiết'!$C:$J,8,0),"") | ... T20: =IFERROR(VLOOKUP($A$2&$A20&T$4,'Bảng giá chi tiết'!$C:$J,8,0),"") | U20: 12
... A27: 19 | B27: =IFERROR(VLOOKUP($A$2&$A27&B$4,'Bảng giá chi tiết'!$C:$J,8,0),"") | C27: =IFERROR(VLOOKUP($A$2&$A27&C$4,'Bảng giá chi tiết'!$C:$J,8,0),"") | D27: =IFERROR(VLOOKUP($A$2&$A27&D$4,'Bảng giá chi tiết'!$C:$J,8,0),"") | E27: =IFERROR(VLOOKUP($A$2&$A27&E$4,'Bảng giá chi tiết'!$C:$J,8,0),"") | F27: =IFERROR(VLOOKUP($A$2&$A27&F$4,'Bảng giá chi tiết'!$C:$J,8,0),"") | G27: =IFERROR(VLOOKUP($A$2&$A27&G$4,'Bảng giá chi tiết'!$C:$J,8,0),"") | H27: =IFERROR(VLOOKUP($A$2&$A27&H$4,'Bảng giá chi tiết'!$C:$J,8,0),"") | I27: =IFERROR(VLOOKUP($A$2&$A27&I$4,'Bảng giá chi tiết'!$C:$J,8,0),"") | ... T27: =IFERROR(VLOOKUP($A$2&$A27&T$4,'Bảng giá chi tiết'!$C:$J,8,0),"") | U27: 19
A28: 20 | B28: =IFERROR(VLOOKUP($A$2&$A28&B$4,'Bảng giá chi tiết'!$C:$J,8,0),"") | C28: =IFERROR(VLOOKUP($A$2&$A28&C$4,'Bảng giá chi tiết'!$C:$J,8,0),"") | D28: =IFERROR(VLOOKUP($A$2&$A28&D$4,'Bảng giá chi tiết'!$C:$J,8,0),"") | E28: =IFERROR(VLOOKUP($A$2&$A28&E$4,'Bảng giá chi tiết'!$C:$J,8,0),"") | F28: =IFERROR(VLOOKUP($A$2&$A28&F$4,'Bảng giá chi tiết'!$C:$J,8,0),"") | G28: =IFERROR(VLOOKUP($A$2&$A28&G$4,'Bảng giá chi tiết'!$C:$J,8,0),"") | H28: =IFERROR(VLOOKUP($A$2&$A28&H$4,'Bảng giá chi tiết'!$C:$J,8,0),"") | I28: =IFERROR(VLOOKUP($A$2&$A28&I$4,'Bảng giá chi tiết'!$C:$J,8,0),"") | ... T28: =IFERROR(VLOOKUP($A$2&$A28&T$4,'Bảng giá chi tiết'!$C:$J,8,0),"") | U28: 20
A29: 21 | B29: =IFERROR(VLOOKUP($A$2&$A29&B$4,'Bảng giá chi tiết'!$C:$J,8,0),"") | C29: =IFERROR(VLOOKUP($A$2&$A29&C$4,'Bảng giá chi tiết'!$C:$J,8,0),"") | D29: =IFERROR(VLOOKUP($A$2&$A29&D$4,'Bảng giá chi tiết'!$C:$J,8,0),"") | E29: =IFERROR(VLOOKUP($A$2&$A29&E$4,'Bảng giá chi tiết'!$C:$J,8,0),"") | F29: =IFERROR(VLOOKUP($A$2&$A29&F$4,'Bảng giá chi tiết'!$C:$J,8,0),"") | G29: =IFERROR(VLOOKUP($A$2&$A29&G$4,'Bảng giá chi tiết'!$C:$J,8,0),"") | H29: =IFERROR(VLOOKUP($A$2&$A29&H$4,'Bảng giá chi tiết'!$C:$J,8,0),"") | I29: =IFERROR(VLOOKUP($A$2&$A29&I$4,'Bảng giá chi tiết'!$C:$J,8,0),"") | ... T29: =IFERROR(VLOOKUP($A$2&$A29&T$4,'Bảng giá chi tiết'!$C:$J,8,0),"") | U29: 21
A30: 22 | B30: =IFERROR(VLOOKUP($A$2&$A30&B$4,'Bảng giá chi tiết'!$C:$J,8,0),"") | C30: =IFERROR(VLOOKUP($A$2&$A30&C$4,'Bảng giá chi tiết'!$C:$J,8,0),"") | D30: =IFERROR(VLOOKUP($A$2&$A30&D$4,'Bảng giá chi tiết'!$C:$J,8,0),"") | E30: =IFERROR(VLOOKUP($A$2&$A30&E$4,'Bảng giá chi tiết'!$C:$J,8,0),"") | F30: =IFERROR(VLOOKUP($A$2&$A30&F$4,'Bảng giá chi tiết'!$C:$J,8,0),"") | G30: =IFERROR(VLOOKUP($A$2&$A30&G$4,'Bảng giá chi tiết'!$C:$J,8,0),"") | H30: =IFERROR(VLOOKUP($A$2&$A30&H$4,'Bảng giá chi tiết'!$C:$J,8,0),"") | I30: =IFERROR(VLOOKUP($A$2&$A30&I$4,'Bảng giá chi tiết'!$C:$J,8,0),"") | ... T30: =IFERROR(VLOOKUP($A$2&$A30&T$4,'Bảng giá chi tiết'!$C:$J,8,0),"") | U30: 22
A31: 23 | B31: =IFERROR(VLOOKUP($A$2&$A31&B$4,'Bảng giá chi tiết'!$C:$J,8,0),"") | C31: =IFERROR(VLOOKUP($A$2&$A31&C$4,'Bảng giá chi tiết'!$C:$J,8,0),"") | D31: =IFERROR(VLOOKUP($A$2&$A31&D$4,'Bảng giá chi tiết'!$C:$J,8,0),"") | E31: =IFERROR(VLOOKUP($A$2&$A31&E$4,'Bảng giá chi tiết'!$C:$J,8,0),"") | F31: =IFERROR(VLOOKUP($A$2&$A31&F$4,'Bảng giá chi tiết'!$C:$J,8,0),"") -> 6520? | G31: =IFERROR(VLOOKUP($A$2&$A31&G$4,'Bảng giá chi tiết'!$C:$J,8,0),"") | H31: =IFERROR(VLOOKUP($A$2&$A31&H$4,'Bảng giá chi tiết'!$C:$J,8,0),"") | I31: =IFERROR(VLOOKUP($A$2&$A31&I$4,'Bảng giá chi tiết'!$C:$J,8,0),"") | ... T31: =IFERROR(VLOOKUP($A$2&$A31&T$4,'Bảng giá chi tiết'!$C:$J,8,0),"") | U31: 23
A32: 24 | B32: =IFERROR(VLOOKUP($A$2&$A32&B$4,'Bảng giá chi tiết'!$C:$J,8,0),"") | C32: =IFERROR(VLOOKUP($A$2&$A32&C$4,'Bảng giá chi tiết'!$C:$J,8,0),"") | D32: =IFERROR(VLOOKUP($A$2&$A32&D$4,'Bảng giá chi tiết'!$C:$J,8,0),"") | E32: =IFERROR(VLOOKUP($A$2&$A32&E$4,'Bảng giá chi tiết'!$C:$J,8,0),"") | F32: =IFERROR(VLOOKUP($A$2&$A32&F$4,'Bảng giá chi tiết'!$C:$J,8,0),"") -> 0? | G32: =IFERROR(VLOOKUP($A$2&$A32&G$4,'Bảng giá chi tiết'!$C:$J,8,0),"") | H32: =IFERROR(VLOOKUP($A$2&$A32&H$4,'Bảng giá chi tiết'!$C:$J,8,0),"") | I32: =IFERROR(VLOOKUP($A$2&$A32&I$4,'Bảng giá chi tiết'!$C:$J,8,0),"") | ... T32: =IFERROR(VLOOKUP($A$2&$A32&T$4,'Bảng giá chi tiết'!$C:$J,8,0),"") | U32: 24
A33: TẦNG/CĂN | B33: 01 | C33: 02 | E33: 03 | G33: 05A | H33: 05 | I33: 06 | J33: 08A | K33: 08 | L33: 09 | M33: 10 | N33: 11 | O33: 12 | P33: 12A | R33: 15A | S33: 15 | T33: 16 | U33: TẦNG/CĂN
A34: Loại căn | B34: DUPLEX | C34: 2BR + 1MR | E34: DUPLEX | G34: 2 BR+ | H34: Studio | I34: 1 BR+ | J34: 1 BR + 1MR | K34: 1 BR + 1MR | L34: Studio | M34: 1 BR+ | N34: 1 BR+ | O34: 1 BR | P34: 2BR + 1MR | R34: DUPLEX | S34: 1 BR+ | T34: 1 BR + 1MR | U34: Loại căn
A35: DT TT | B35: 103,1 | C35: 102,1 | E35: 110,7 | G35: 65,2 | H35: 29,4 | I35: 45,6 | J35: 59,5 | K35: 59,8 | L35: 30 | M35: 45,7 | N35: 45,7 | O35: 40,8 | P35: 96,3 | R35: 100,4 | S35: 46,8 | T35: 60,3 | U35: DT TT
A36: 25 | B36: =IFERROR(VLOOKUP($A$2&$A36&B$4,'Bảng giá chi tiết'!$C:$J,8,0),"") | C36: =IFERROR(VLOOKUP($A$2&$A36&C$4,'Bảng giá chi tiết'!$C:$J,8,0),"") | D36: =IFERROR(VLOOKUP($A$2&$A36&D$4,'Bảng giá chi tiết'!$C:$J,8,0),"") | E36: =IFERROR(VLOOKUP($A$2&$A36&E$4,'Bảng giá chi tiết'!$C:$J,8,0),"") | F36: =IFERROR(VLOOKUP($A$2&$A36&F$4,'Bảng giá chi tiết'!$C:$J,8,0),"") | G36: =IFERROR(VLOOKUP($A$2&$A36&G$4,'Bảng giá chi tiết'!$C:$J,8,0),"") | H36: =IFERROR(VLOOKUP($A$2&$A36&H$4,'Bảng giá chi tiết'!$C:$J,8,0),"") | I36: =IFERROR(VLOOKUP($A$2&$A36&I$4,'Bảng giá chi tiết'!$C:$J,8,0),"") | ... T36: =IFERROR(VLOOKUP($A$2&$A36&T$4,'Bảng giá chi tiết'!$C:$J,8,0),"") | U36: 25
A37: TẦNG/CĂN | C37: 01 | G37: 02 | I37: 03 | J37: 05A | S37: 05 | T37: 06 | U37: TẦNG/CĂN
A38: Loại căn | B38: DUPLEX | C38: 3 BR | E38: DUPLEX | G38: 3 BR | I38: 1 BR+ | J38: 2 BR | R38: DUPLEX | S38: 1 BR+ | T38: 2 BR | U38: Loại căn
A39: DT TT | B39: 80,9 | C39: 98,9 | E39: 84,1 | G39: 106,3 | I39: 45,5 | J39: 58,8 | R39: 69,8 | S39: 46,6 | T39: 59,5 | U39: DT TT
A40: 26 | B40: =IFERROR(__xludf.DUMMYFUNCTION("ARRAYFORMULA( IF( IMPORTRANGE(""1Eot2b28R3MqVuoQdclpaU-BSV2lEsjsopqYknLqiKPg"", ""C1 - CT!B40:T40"")<>"""", HYPERLINK( REGEXEXTRACT(IMPORTRANGE(""1Eot2b28R3MqVuoQdclpaU-BSV2lEsjsopqYknLqiKPg"",""C1 - CT!B40:T40""), ""\n(.+)"&"""), REGEXEXTRACT(IMPORTRANGE(""1Eot2b28R3MqVuoQdclpaU-BSV2lEsjsopqYknLqiKPg"", ""C1 - CT!B40:T40""), ""^(.+)\n"")), """" ) )"),"#REF!") -> #REF! | U40: 26
A41: TẦNG/CĂN | C41: 01 | G41: 02 | R41: 03 | U41: TẦNG/CĂN
A42: Loại căn | C42: PENHOUSE | G42: PENHOUSE | R42: PENHOUSE | U42: Loại căn
A43: DT TT | C43: 191,4 | G43: 192,3 | R43: 187,2 | U43: DT TT
A44: 27 | U44: 27

Sheet C2-CT 
D1: CẬP NHẬT BẢNG HÀNG TÒA C2 - PHÂN KHU CENTRAL SQUARE
A2: C2Z2- | D2: Ngày cập nhật: | G2: =TODAY() -> 46212 | L2: Quỹ chung | N2: Độc quyền | P2: Đã bán | R2: Quỹ chéo
A4: TẦNG/CĂN | B4: -01 | C4: -02 | D4: -03 | E4: -05A | F4: -05 | G4: -06 | H4: -08A | I4: -08 | J4: -09 | K4: -10 | L4: -11 | M4: -12 | N4: -12A | O4: -15A | P4: -15 | Q4: -16 | R4: -18A | S4: -18 | T4: -19 | U4: TẦNG/CĂN
A5: Loại căn | B5: 3 BR | C5: 1 BR | D5: 2 BR | E5: 1 BR+ | F5: 2 BR+ | G5: 2 BR | H5: 1 BR+ | I5: 1 BR+ | J5: 2 BR | K5: 2 BR+ | L5: 1 BR+ | M5: 2 BR | N5: 1 BR | O5: Studio | P5: 2 BR+ | Q5: 2 BR+ | R5: Studio | S5: 1 BR+ | T5: 2 BR | U5: Loại căn
A6: DT TT | B6: 100,3 | C6: 39,3 | D6: 58 | E6: 45,4 | F6: 65,1 | G6: 61,4 | H6: 45,5 | I6: 45,5 | J6: 58,8 | K6: 65,8 | L6: 45,5 | M6: 58,4 | N6: 41,8 | O6: 28,8 | P6: 65,6 | Q6: 67,4 | R6: 31,7 | S6: 45,6 | T6: 59,5 | U6: DT TT
A7: Hướng ban công | B7: ĐB | C7: ĐB | D7: ĐB | E7: ĐB | F7: ĐB - ĐN | G7: ĐN - TN | H7: TN | I7: TN | J7: TN | K7: TN | L7: TN | M7: TN | N7: TN | O7: TN | P7: TN - TB | Q7: TB - ĐB | R7: ĐB | S7: ĐB | T7: ĐB | U7: Hướng ban công
A8: View | B8: View Công viên | G8: View Nội khu | Q8: View Công viên | U8: View
A9: 01 | B9: =IFERROR(VLOOKUP($A$2&$A9&B$4,'Bảng giá chi tiết'!$C:$J,8,0),"") | C9: =IFERROR(VLOOKUP($A$2&$A9&C$4,'Bảng giá chi tiết'!$C:$J,8,0),"") | D9: =IFERROR(VLOOKUP($A$2&$A9&D$4,'Bảng giá chi tiết'!$C:$J,8,0),"") | E9: =IFERROR(VLOOKUP($A$2&$A9&E$4,'Bảng giá chi tiết'!$C:$J,8,0),"") | F9: =IFERROR(VLOOKUP($A$2&$A9&F$4,'Bảng giá chi tiết'!$C:$J,8,0),"") | G9: =IFERROR(VLOOKUP($A$2&$A9&G$4,'Bảng giá chi tiết'!$C:$J,8,0),"") | H9: =IFERROR(VLOOKUP($A$2&$A9&H$4,'Bảng giá chi tiết'!$C:$J,8,0),"") | I9: =IFERROR(VLOOKUP($A$2&$A9&I$4,'Bảng giá chi tiết'!$C:$J,8,0),"") | ... T9: =IFERROR(VLOOKUP($A$2&$A9&T$4,'Bảng giá chi tiết'!$C:$J,8,0),"") | U9: 01
A10: 02 | B10: =IFERROR(VLOOKUP($A$2&$A10&B$4,'Bảng giá chi tiết'!$C:$J,8,0),"") | C10: =IFERROR(VLOOKUP($A$2&$A10&C$4,'Bảng giá chi tiết'!$C:$J,8,0),"") | D10: =IFERROR(VLOOKUP($A$2&$A10&D$4,'Bảng giá chi tiết'!$C:$J,8,0),"") | E10: =IFERROR(VLOOKUP($A$2&$A10&E$4,'Bảng giá chi tiết'!$C:$J,8,0),"") | F10: =IFERROR(VLOOKUP($A$2&$A10&F$4,'Bảng giá chi tiết'!$C:$J,8,0),"") | G10: =IFERROR(VLOOKUP($A$2&$A10&G$4,'Bảng giá chi tiết'!$C:$J,8,0),"") | H10: =IFERROR(VLOOKUP($A$2&$A10&H$4,'Bảng giá chi tiết'!$C:$J,8,0),"") | I10: =IFERROR(VLOOKUP($A$2&$A10&I$4,'Bảng giá chi tiết'!$C:$J,8,0),"") | ... T10: =IFERROR(VLOOKUP($A$2&$A10&T$4,'Bảng giá chi tiết'!$C:$J,8,0),"") | U10: 02
A11: 03 | B11: =IFERROR(VLOOKUP($A$2&$A11&B$4,'Bảng giá chi tiết'!$C:$J,8,0),"") | C11: =IFERROR(VLOOKUP($A$2&$A11&C$4,'Bảng giá chi tiết'!$C:$J,8,0),"") | D11: =IFERROR(VLOOKUP($A$2&$A11&D$4,'Bảng giá chi tiết'!$C:$J,8,0),"") | E11: =IFERROR(VLOOKUP($A$2&$A11&E$4,'Bảng giá chi tiết'!$C:$J,8,0),"") | F11: =IFERROR(VLOOKUP($A$2&$A11&F$4,'Bảng giá chi tiết'!$C:$J,8,0),"") | G11: =IFERROR(VLOOKUP($A$2&$A11&G$4,'Bảng giá chi tiết'!$C:$J,8,0),"") | H11: =IFERROR(VLOOKUP($A$2&$A11&H$4,'Bảng giá chi tiết'!$C:$J,8,0),"") | I11: =IFERROR(VLOOKUP($A$2&$A11&I$4,'Bảng giá chi tiết'!$C:$J,8,0),"") | ... T11: =IFERROR(VLOOKUP($A$2&$A11&T$4,'Bảng giá chi tiết'!$C:$J,8,0),"") | U11: 03
A12: 04 | B12: =IFERROR(VLOOKUP($A$2&$A12&B$4,'Bảng giá chi tiết'!$C:$J,8,0),"") | C12: =IFERROR(VLOOKUP($A$2&$A12&C$4,'Bảng giá chi tiết'!$C:$J,8,0),"") | D12: =IFERROR(VLOOKUP($A$2&$A12&D$4,'Bảng giá chi tiết'!$C:$J,8,0),"") | E12: =IFERROR(VLOOKUP($A$2&$A12&E$4,'Bảng giá chi tiết'!$C:$J,8,0),"") | F12: =IFERROR(VLOOKUP($A$2&$A12&F$4,'Bảng giá chi tiết'!$C:$J,8,0),"") | G12: =IFERROR(VLOOKUP($A$2&$A12&G$4,'Bảng giá chi tiết'!$C:$J,8,0),"") | H12: =IFERROR(VLOOKUP($A$2&$A12&H$4,'Bảng giá chi tiết'!$C:$J,8,0),"") | I12: =IFERROR(VLOOKUP($A$2&$A12&I$4,'Bảng giá chi tiết'!$C:$J,8,0),"") | ... T12: =IFERROR(VLOOKUP($A$2&$A12&T$4,'Bảng giá chi tiết'!$C:$J,8,0),"") | U12: 04
A13: 05 | B13: =IFERROR(VLOOKUP($A$2&$A13&B$4,'Bảng giá chi tiết'!$C:$J,8,0),"") | C13: =IFERROR(VLOOKUP($A$2&$A13&C$4,'Bảng giá chi tiết'!$C:$J,8,0),"") | D13: =IFERROR(VLOOKUP($A$2&$A13&D$4,'Bảng giá chi tiết'!$C:$J,8,0),"") | E13: =IFERROR(VLOOKUP($A$2&$A13&E$4,'Bảng giá chi tiết'!$C:$J,8,0),"") | F13: =IFERROR(VLOOKUP($A$2&$A13&F$4,'Bảng giá chi tiết'!$C:$J,8,0),"") | G13: =IFERROR(VLOOKUP($A$2&$A13&G$4,'Bảng giá chi tiết'!$C:$J,8,0),"") | H13: =IFERROR(VLOOKUP($A$2&$A13&H$4,'Bảng giá chi tiết'!$C:$J,8,0),"") | I13: =IFERROR(VLOOKUP($A$2&$A13&I$4,'Bảng giá chi tiết'!$C:$J,8,0),"") -> 4013? | ... T13: =IFERROR(VLOOKUP($A$2&$A13&T$4,'Bảng giá chi tiết'!$C:$J,8,0),"") | U13: 05
A14: 06 | B14: =IFERROR(VLOOKUP($A$2&$A14&B$4,'Bảng giá chi tiết'!$C:$J,8,0),"") | C14: =IFERROR(VLOOKUP($A$2&$A14&C$4,'Bảng giá chi tiết'!$C:$J,8,0),"") | D14: =IFERROR(VLOOKUP($A$2&$A14&D$4,'Bảng giá chi tiết'!$C:$J,8,0),"") | E14: =IFERROR(VLOOKUP($A$2&$A14&E$4,'Bảng giá chi tiết'!$C:$J,8,0),"") | F14: =IFERROR(VLOOKUP($A$2&$A14&F$4,'Bảng giá chi tiết'!$C:$J,8,0),"") | G14: =IFERROR(VLOOKUP($A$2&$A14&G$4,'Bảng giá chi tiết'!$C:$J,8,0),"") | H14: =IFERROR(VLOOKUP($A$2&$A14&H$4,'Bảng giá chi tiết'!$C:$J,8,0),"") -> 0? | I14: =IFERROR(VLOOKUP($A$2&$A14&I$4,'Bảng giá chi tiết'!$C:$J,8,0),"") | ... T14: =IFERROR(VLOOKUP($A$2&$A14&T$4,'Bảng giá chi tiết'!$C:$J,8,0),"") | U14: 06
A15: 07 | B15: =IFERROR(VLOOKUP($A$2&$A15&B$4,'Bảng giá chi tiết'!$C:$J,8,0),"") | C15: =IFERROR(VLOOKUP($A$2&$A15&C$4,'Bảng giá chi tiết'!$C:$J,8,0),"") | D15: =IFERROR(VLOOKUP($A$2&$A15&D$4,'Bảng giá chi tiết'!$C:$J,8,0),"") | E15: =IFERROR(VLOOKUP($A$2&$A15&E$4,'Bảng giá chi tiết'!$C:$J,8,0),"") | F15: =IFERROR(VLOOKUP($A$2&$A15&F$4,'Bảng giá chi tiết'!$C:$J,8,0),"") | G15: =IFERROR(VLOOKUP($A$2&$A15&G$4,'Bảng giá chi tiết'!$C:$J,8,0),"") -> 0? | H15: =IFERROR(VLOOKUP($A$2&$A15&H$4,'Bảng giá chi tiết'!$C:$J,8,0),"") -> 0? | I15: =IFERROR(VLOOKUP($A$2&$A15&I$4,'Bảng giá chi tiết'!$C:$J,8,0),"") -> 0? | ... T15: =IFERROR(VLOOKUP($A$2&$A15&T$4,'Bảng giá chi tiết'!$C:$J,8,0),"") | U15: 07
A16: 08 | B16: =IFERROR(VLOOKUP($A$2&$A16&B$4,'Bảng giá chi tiết'!$C:$J,8,0),"") | C16: =IFERROR(VLOOKUP($A$2&$A16&C$4,'Bảng giá chi tiết'!$C:$J,8,0),"") | D16: =IFERROR(VLOOKUP($A$2&$A16&D$4,'Bảng giá chi tiết'!$C:$J,8,0),"") | E16: =IFERROR(VLOOKUP($A$2&$A16&E$4,'Bảng giá chi tiết'!$C:$J,8,0),"") | F16: =IFERROR(VLOOKUP($A$2&$A16&F$4,'Bảng giá chi tiết'!$C:$J,8,0),"") | G16: =IFERROR(VLOOKUP($A$2&$A16&G$4,'Bảng giá chi tiết'!$C:$J,8,0),"") -> 0? | H16: =IFERROR(VLOOKUP($A$2&$A16&H$4,'Bảng giá chi tiết'!$C:$J,8,0),"") | I16: =IFERROR(VLOOKUP($A$2&$A16&I$4,'Bảng giá chi tiết'!$C:$J,8,0),"") -> 0? | ... T16: =IFERROR(VLOOKUP($A$2&$A16&T$4,'Bảng giá chi tiết'!$C:$J,8,0),"") | U16: 08
A17: 09 | B17: =IFERROR(VLOOKUP($A$2&$A17&B$4,'Bảng giá chi tiết'!$C:$J,8,0),"") | C17: =IFERROR(VLOOKUP($A$2&$A17&C$4,'Bảng giá chi tiết'!$C:$J,8,0),"") | D17: =IFERROR(VLOOKUP($A$2&$A17&D$4,'Bảng giá chi tiết'!$C:$J,8,0),"") | E17: =IFERROR(VLOOKUP($A$2&$A17&E$4,'Bảng giá chi tiết'!$C:$J,8,0),"") | F17: =IFERROR(VLOOKUP($A$2&$A17&F$4,'Bảng giá chi tiết'!$C:$J,8,0),"") | G17: =IFERROR(VLOOKUP($A$2&$A17&G$4,'Bảng giá chi tiết'!$C:$J,8,0),"") | H17: =IFERROR(VLOOKUP($A$2&$A17&H$4,'Bảng giá chi tiết'!$C:$J,8,0),"") | I17: =IFERROR(VLOOKUP($A$2&$A17&I$4,'Bảng giá chi tiết'!$C:$J,8,0),"") | ... T17: =IFERROR(VLOOKUP($A$2&$A17&T$4,'Bảng giá chi tiết'!$C:$J,8,0),"") | U17: 09
A18: 10 | B18: =IFERROR(VLOOKUP($A$2&$A18&B$4,'Bảng giá chi tiết'!$C:$J,8,0),"") | C18: =IFERROR(VLOOKUP($A$2&$A18&C$4,'Bảng giá chi tiết'!$C:$J,8,0),"") | D18: =IFERROR(VLOOKUP($A$2&$A18&D$4,'Bảng giá chi tiết'!$C:$J,8,0),"") | E18: =IFERROR(VLOOKUP($A$2&$A18&E$4,'Bảng giá chi tiết'!$C:$J,8,0),"") | F18: =IFERROR(VLOOKUP($A$2&$A18&F$4,'Bảng giá chi tiết'!$C:$J,8,0),"") | G18: =IFERROR(VLOOKUP($A$2&$A18&G$4,'Bảng giá chi tiết'!$C:$J,8,0),"") | H18: =IFERROR(VLOOKUP($A$2&$A18&H$4,'Bảng giá chi tiết'!$C:$J,8,0),"") | I18: =IFERROR(VLOOKUP($A$2&$A18&I$4,'Bảng giá chi tiết'!$C:$J,8,0),"") | ... T18: =IFERROR(VLOOKUP($A$2&$A18&T$4,'Bảng giá chi tiết'!$C:$J,8,0),"") | U18: 10
A19: 11 | B19: =IFERROR(VLOOKUP($A$2&$A19&B$4,'Bảng giá chi tiết'!$C:$J,8,0),"") | C19: =IFERROR(VLOOKUP($A$2&$A19&C$4,'Bảng giá chi tiết'!$C:$J,8,0),"") | D19: =IFERROR(VLOOKUP($A$2&$A19&D$4,'Bảng giá chi tiết'!$C:$J,8,0),"") | E19: =IFERROR(VLOOKUP($A$2&$A19&E$4,'Bảng giá chi tiết'!$C:$J,8,0),"") | F19: =IFERROR(VLOOKUP($A$2&$A19&F$4,'Bảng giá chi tiết'!$C:$J,8,0),"") | G19: =IFERROR(VLOOKUP($A$2&$A19&G$4,'Bảng giá chi tiết'!$C:$J,8,0),"") -> 6407? | H19: =IFERROR(VLOOKUP($A$2&$A19&H$4,'Bảng giá chi tiết'!$C:$J,8,0),"") | I19: =IFERROR(VLOOKUP($A$2&$A19&I$4,'Bảng giá chi tiết'!$C:$J,8,0),"") -> 4392? | ... T19: =IFERROR(VLOOKUP($A$2&$A19&T$4,'Bảng giá chi tiết'!$C:$J,8,0),"") | U19: 11
A20: 12 | B20: =IFERROR(VLOOKUP($A$2&$A20&B$4,'Bảng giá chi tiết'!$C:$J,8,0),"") | C20: =IFERROR(VLOOKUP($A$2&$A20&C$4,'Bảng giá chi tiết'!$C:$J,8,0),"") | D20: =IFERROR(VLOOKUP($A$2&$A20&D$4,'Bảng giá chi tiết'!$C:$J,8,0),"") | E20: =IFERROR(VLOOKUP($A$2&$A20&E$4,'Bảng giá chi tiết'!$C:$J,8,0),"") | F20: =IFERROR(VLOOKUP($A$2&$A20&F$4,'Bảng giá chi tiết'!$C:$J,8,0),"") -> 0? | G20: =IFERROR(VLOOKUP($A$2&$A20&G$4,'Bảng giá chi tiết'!$C:$J,8,0),"") -> 0? | H20: =IFERROR(VLOOKUP($A$2&$A20&H$4,'Bảng giá chi tiết'!$C:$J,8,0),"") | I20: =IFERROR(VLOOKUP($A$2&$A20&I$4,'Bảng giá chi tiết'!$C:$J,8,0),"") | ... T20: =IFERROR(VLOOKUP($A$2&$A20&T$4,'Bảng giá chi tiết'!$C:$J,8,0),"") | U20: 12
... A27: 19 | B27: =IFERROR(VLOOKUP($A$2&$A27&B$4,'Bảng giá chi tiết'!$C:$J,8,0),"") | C27: =IFERROR(VLOOKUP($A$2&$A27&C$4,'Bảng giá chi tiết'!$C:$J,8,0),"") | D27: =IFERROR(VLOOKUP($A$2&$A27&D$4,'Bảng giá chi tiết'!$C:$J,8,0),"") | E27: =IFERROR(VLOOKUP($A$2&$A27&E$4,'Bảng giá chi tiết'!$C:$J,8,0),"") | F27: =IFERROR(VLOOKUP($A$2&$A27&F$4,'Bảng giá chi tiết'!$C:$J,8,0),"") | G27: =IFERROR(VLOOKUP($A$2&$A27&G$4,'Bảng giá chi tiết'!$C:$J,8,0),"") | H27: =IFERROR(VLOOKUP($A$2&$A27&H$4,'Bảng giá chi tiết'!$C:$J,8,0),"") | I27: =IFERROR(VLOOKUP($A$2&$A27&I$4,'Bảng giá chi tiết'!$C:$J,8,0),"") | ... T27: =IFERROR(VLOOKUP($A$2&$A27&T$4,'Bảng giá chi tiết'!$C:$J,8,0),"") | U27: 19
A28: 20 | B28: =IFERROR(VLOOKUP($A$2&$A28&B$4,'Bảng giá chi tiết'!$C:$J,8,0),"") | C28: =IFERROR(VLOOKUP($A$2&$A28&C$4,'Bảng giá chi tiết'!$C:$J,8,0),"") | D28: =IFERROR(VLOOKUP($A$2&$A28&D$4,'Bảng giá chi tiết'!$C:$J,8,0),"") | E28: =IFERROR(VLOOKUP($A$2&$A28&E$4,'Bảng giá chi tiết'!$C:$J,8,0),"") | F28: =IFERROR(VLOOKUP($A$2&$A28&F$4,'Bảng giá chi tiết'!$C:$J,8,0),"") | G28: =IFERROR(VLOOKUP($A$2&$A28&G$4,'Bảng giá chi tiết'!$C:$J,8,0),"") -> 0? | H28: =IFERROR(VLOOKUP($A$2&$A28&H$4,'Bảng giá chi tiết'!$C:$J,8,0),"") | I28: =IFERROR(VLOOKUP($A$2&$A28&I$4,'Bảng giá chi tiết'!$C:$J,8,0),"") | ... T28: =IFERROR(VLOOKUP($A$2&$A28&T$4,'Bảng giá chi tiết'!$C:$J,8,0),"") | U28: 20
A29: 21 | B29: =IFERROR(VLOOKUP($A$2&$A29&B$4,'Bảng giá chi tiết'!$C:$J,8,0),"") | C29: =IFERROR(VLOOKUP($A$2&$A29&C$4,'Bảng giá chi tiết'!$C:$J,8,0),"") | D29: =IFERROR(VLOOKUP($A$2&$A29&D$4,'Bảng giá chi tiết'!$C:$J,8,0),"") -> 0? | E29: =IFERROR(VLOOKUP($A$2&$A29&E$4,'Bảng giá chi tiết'!$C:$J,8,0),"") | F29: =IFERROR(VLOOKUP($A$2&$A29&F$4,'Bảng giá chi tiết'!$C:$J,8,0),"") | G29: =IFERROR(VLOOKUP($A$2&$A29&G$4,'Bảng giá chi tiết'!$C:$J,8,0),"") -> 0? | H29: =IFERROR(VLOOKUP($A$2&$A29&H$4,'Bảng giá chi tiết'!$C:$J,8,0),"") | I29: =IFERROR(VLOOKUP($A$2&$A29&I$4,'Bảng giá chi tiết'!$C:$J,8,0),"") -> 0? | ... T29: =IFERROR(VLOOKUP($A$2&$A29&T$4,'Bảng giá chi tiết'!$C:$J,8,0),"") | U29: 21
A30: 22 | B30: =IFERROR(VLOOKUP($A$2&$A30&B$4,'Bảng giá chi tiết'!$C:$J,8,0),"") | C30: =IFERROR(VLOOKUP($A$2&$A30&C$4,'Bảng giá chi tiết'!$C:$J,8,0),"") | D30: =IFERROR(VLOOKUP($A$2&$A30&D$4,'Bảng giá chi tiết'!$C:$J,8,0),"") | E30: =IFERROR(VLOOKUP($A$2&$A30&E$4,'Bảng giá chi tiết'!$C:$J,8,0),"") | F30: =IFERROR(VLOOKUP($A$2&$A30&F$4,'Bảng giá chi tiết'!$C:$J,8,0),"") | G30: =IFERROR(VLOOKUP($A$2&$A30&G$4,'Bảng giá chi tiết'!$C:$J,8,0),"") | H30: =IFERROR(VLOOKUP($A$2&$A30&H$4,'Bảng giá chi tiết'!$C:$J,8,0),"") | I30: =IFERROR(VLOOKUP($A$2&$A30&I$4,'Bảng giá chi tiết'!$C:$J,8,0),"") | ... T30: =IFERROR(VLOOKUP($A$2&$A30&T$4,'Bảng giá chi tiết'!$C:$J,8,0),"") | U30: 22
A31: 23 | B31: =IFERROR(VLOOKUP($A$2&$A31&B$4,'Bảng giá chi tiết'!$C:$J,8,0),"") | C31: =IFERROR(VLOOKUP($A$2&$A31&C$4,'Bảng giá chi tiết'!$C:$J,8,0),"") | D31: =IFERROR(VLOOKUP($A$2&$A31&D$4,'Bảng giá chi tiết'!$C:$J,8,0),"") | E31: =IFERROR(VLOOKUP($A$2&$A31&E$4,'Bảng giá chi tiết'!$C:$J,8,0),"") | F31: =IFERROR(VLOOKUP($A$2&$A31&F$4,'Bảng giá chi tiết'!$C:$J,8,0),"") | G31: =IFERROR(VLOOKUP($A$2&$A31&G$4,'Bảng giá chi tiết'!$C:$J,8,0),"") -> 0? | H31: =IFERROR(VLOOKUP($A$2&$A31&H$4,'Bảng giá chi tiết'!$C:$J,8,0),"") | I31: =IFERROR(VLOOKUP($A$2&$A31&I$4,'Bảng giá chi tiết'!$C:$J,8,0),"") | ... T31: =IFERROR(VLOOKUP($A$2&$A31&T$4,'Bảng giá chi tiết'!$C:$J,8,0),"") | U31: 23
A32: 24 | B32: =IFERROR(VLOOKUP($A$2&$A32&B$4,'Bảng giá chi tiết'!$C:$J,8,0),"") | C32: =IFERROR(VLOOKUP($A$2&$A32&C$4,'Bảng giá chi tiết'!$C:$J,8,0),"") | D32: =IFERROR(VLOOKUP($A$2&$A32&D$4,'Bảng giá chi tiết'!$C:$J,8,0),"") | E32: =IFERROR(VLOOKUP($A$2&$A32&E$4,'Bảng giá chi tiết'!$C:$J,8,0),"") -> 0? | F32: =IFERROR(VLOOKUP($A$2&$A32&F$4,'Bảng giá chi tiết'!$C:$J,8,0),"") -> 0? | G32: =IFERROR(VLOOKUP($A$2&$A32&G$4,'Bảng giá chi tiết'!$C:$J,8,0),"") -> 0? | H32: =IFERROR(VLOOKUP($A$2&$A32&H$4,'Bảng giá chi tiết'!$C:$J,8,0),"") | I32: =IFERROR(VLOOKUP($A$2&$A32&I$4,'Bảng giá chi tiết'!$C:$J,8,0),"") | ... T32: =IFERROR(VLOOKUP($A$2&$A32&T$4,'Bảng giá chi tiết'!$C:$J,8,0),"") | U32: 24
A33: TẦNG/CĂN | B33: 01 | C33: 02 | D33: 03 | E33: 05A | G33: 05 | I33: 06 | J33: 08A | K33: 08 | L33: 09 | M33: 10 | N33: 11 | O33: 12 | P33: 12A | Q33: 15A | S33: 15 | T33: 16 | U33: TẦNG/CĂN
A34: Loại căn | B34: DUPLEX | C34: 1 BR | D34: 2 BR | E34: DUPLEX | G34: 3 BR | I34: 1 BR+ | J34: 2 BR | K34: 2 BR+ | L34: 1 BR+ | M34: 2 BR | N34: 1 BR | O34: Studio | P34: 2 BR+ | Q34: DUPLEX | S34: 1 BR+ | T34: 2 BR | U34: Loại căn
A35: DT TT | B35: 100,4 | C35: 39,3 | D35: 58 | E35: 112 | G35: 106,3 | I35: 45,5 | J35: 58,8 | K35: 65,8 | L35: 45,5 | M35: 58,4 | N35: 41,8 | O35: 28,8 | P35: 65,6 | Q35: 99,4 | S35: 45,6 | T35: 59,5 | U35: DT TT
A36: 25 | B36: =IFERROR(VLOOKUP($A$2&$A36&B$4,'Bảng giá chi tiết'!$C:$J,8,0),"") | C36: =IFERROR(VLOOKUP($A$2&$A36&C$4,'Bảng giá chi tiết'!$C:$J,8,0),"") | D36: =IFERROR(VLOOKUP($A$2&$A36&D$4,'Bảng giá chi tiết'!$C:$J,8,0),"") | E36: =IFERROR(VLOOKUP($A$2&$A36&E$4,'Bảng giá chi tiết'!$C:$J,8,0),"") | F36: =IFERROR(VLOOKUP($A$2&$A36&F$4,'Bảng giá chi tiết'!$C:$J,8,0),"") | G36: =IFERROR(VLOOKUP($A$2&$A36&G$4,'Bảng giá chi tiết'!$C:$J,8,0),"") -> 6512? | H36: =IFERROR(VLOOKUP($A$2&$A36&H$4,'Bảng giá chi tiết'!$C:$J,8,0),"") | I36: =IFERROR(VLOOKUP($A$2&$A36&I$4,'Bảng giá chi tiết'!$C:$J,8,0),"") | ... T36: =IFERROR(VLOOKUP($A$2&$A36&T$4,'Bảng giá chi tiết'!$C:$J,8,0),"") | U36: 25
A37: TẦNG/CĂN | C37: 01 | G37: 02 | I37: 03 | J37: 05A | S37: 05 | T37: 06 | U37: TẦNG/CĂN
A38: Loại căn | B38: DUPLEX | C38: 3 BR | E38: DUPLEX | G38: 3 BR | I38: 1 BR+ | J38: 2 BR | Q38: DUPLEX | S38: 1 BR+ | T38: 2 BR | U38: Loại căn
A39: DT TT | B39: 80,9 | C39: 98,9 | E39: 84,1 | G39: 106,3 | I39: 45,5 | J39: 58,8 | Q39: 69,8 | S39: 45,6 | T39: 59,5 | U39: DT TT
A40: 26 | B40: =IFERROR(__xludf.DUMMYFUNCTION("ARRAYFORMULA( IF( IMPORTRANGE(""1Eot2b28R3MqVuoQdclpaU-BSV2lEsjsopqYknLqiKPg"", ""C2 - CT!B40:T40"")<>"""", HYPERLINK( REGEXEXTRACT(IMPORTRANGE(""1Eot2b28R3MqVuoQdclpaU-BSV2lEsjsopqYknLqiKPg"", ""C2 - CT!B40:T40""), ""\n(.+"&")""), REGEXEXTRACT(IMPORTRANGE(""1Eot2b28R3MqVuoQdclpaU-BSV2lEsjsopqYknLqiKPg"", ""C2 - CT!B40:T40""), ""^(.+)\n"")), """" ) )"),"#REF!") -> #REF! | U40: 26
A41: TẦNG/CĂN | C41: 01 | F41: 02 | Q41: 03 | U41: TẦNG/CĂN
A42: Loại căn | C42: PENHOUSE | F42: PENHOUSE | Q42: PENHOUSE | U42: Loại căn
A43: DT TT | C43: 191,4 | F43: 192,3 | Q43: 187,9 | U43: DT TT
A44: 27 | U44: 27

Sheet C3-CT
D1: CẬP NHẬT BẢNG HÀNG TÒA C3 - PHÂN KHU CENTRAL SQUARE
A2: C2Z3- | D2: Ngày cập nhật: | G2: =TODAY() -> 46212 | L2: Quỹ chung | N2: Độc quyền ( , ) | P2: Đã bán | R2: Quỹ chéo ( ? )
A4: TẦNG/CĂN | B4: -01 | C4: -02 | D4: -03 | E4: -05A | F4: -05 | G4: -06 | H4: -08A | I4: -08 | J4: -09 | K4: -10 | L4: -11 | M4: -12 | N4: -12A | O4: -15A | P4: -15 | Q4: -16 | R4: -18A | S4: -18 | T4: -19 | U4: TẦNG/CĂN
A5: Loại căn | B5: 1 BR + 1MR | C5: 1 BR+ | D5: Studio | E5: 2 BR+ | F5: 2 BR+ | G5: 1 BR+ | H5: 1 BR | I5: 1 BR + 1MR | J5: 2BR + 1MR | K5: 1 BR + 1MR | L5: 1 BR+ | M5: 2BR + 1MR | N5: 2 BR+ | O5: Studio | P5: 1 BR | Q5: 1 BR+ | R5: 1 BR+ | S5: Studio | T5: 1 BR + 1MR | U5: Loại căn
A6: DT TT | B6: 59,5 | C6: 45,8 | D6: 29,4 | E6: 65,2 | F6: 65,2 | G6: 45,5 | H6: 38,6 | I6: 61,6 | J6: 103 | K6: 60,3 | L6: 46,8 | M6: 100,1 | N6: 65,5 | O6: 30,7 | P6: 40,8 | Q6: 45,7 | R6: 45,7 | S6: 30 | T6: 59,8 | U6: DT TT
A7: Hướng ban công | B7: TN | C7: TN | D7: TN | E7: TN - TB | F7: TB - ĐB | G7: ĐB | H7: ĐB | I7: ĐB | J7: ĐB - ĐN | K7: ĐB | L7: ĐB | M7: ĐB - ĐN | N7: ĐN - TN | O7: TN | P7: TN | Q7: TN | R7: TN | S7: TN | T7: TN - TB | U7: Hướng ban công
A8: View | B8: View Nội khu - Công viên | G8: View Biệt thự thấp tầng, đường lớn | R8: View Nội khu - Công viên | U8: View
A9: 01 | B9: =IFERROR(VLOOKUP($A$2&$A9&B$4,'Bảng giá chi tiết'!$C:$J,8,0),"") | C9: =IFERROR(VLOOKUP($A$2&$A9&C$4,'Bảng giá chi tiết'!$C:$J,8,0),"") | D9: =IFERROR(VLOOKUP($A$2&$A9&D$4,'Bảng giá chi tiết'!$C:$J,8,0),"") | E9: =IFERROR(VLOOKUP($A$2&$A9&E$4,'Bảng giá chi tiết'!$C:$J,8,0),"") | F9: =IFERROR(VLOOKUP($A$2&$A9&F$4,'Bảng giá chi tiết'!$C:$J,8,0),"") | G9: =IFERROR(VLOOKUP($A$2&$A9&G$4,'Bảng giá chi tiết'!$C:$J,8,0),"") | H9: =IFERROR(VLOOKUP($A$2&$A9&H$4,'Bảng giá chi tiết'!$C:$J,8,0),"") | I9: =IFERROR(VLOOKUP($A$2&$A9&I$4,'Bảng giá chi tiết'!$C:$J,8,0),"") | ... T9: =IFERROR(VLOOKUP($A$2&$A9&T$4,'Bảng giá chi tiết'!$C:$J,8,0),"") | U9: 01
A10: 02 | B10: =IFERROR(VLOOKUP($A$2&$A10&B$4,'Bảng giá chi tiết'!$C:$J,8,0),"") | C10: =IFERROR(VLOOKUP($A$2&$A10&C$4,'Bảng giá chi tiết'!$C:$J,8,0),"") | D10: =IFERROR(VLOOKUP($A$2&$A10&D$4,'Bảng giá chi tiết'!$C:$J,8,0),"") | E10: =IFERROR(VLOOKUP($A$2&$A10&E$4,'Bảng giá chi tiết'!$C:$J,8,0),"") | F10: =IFERROR(VLOOKUP($A$2&$A10&F$4,'Bảng giá chi tiết'!$C:$J,8,0),"") | G10: =IFERROR(VLOOKUP($A$2&$A10&G$4,'Bảng giá chi tiết'!$C:$J,8,0),"") | H10: =IFERROR(VLOOKUP($A$2&$A10&H$4,'Bảng giá chi tiết'!$C:$J,8,0),"") | I10: =IFERROR(VLOOKUP($A$2&$A10&I$4,'Bảng giá chi tiết'!$C:$J,8,0),"") | ... T10: =IFERROR(VLOOKUP($A$2&$A10&T$4,'Bảng giá chi tiết'!$C:$J,8,0),"") | U10: 02
A11: 03 | B11: =IFERROR(VLOOKUP($A$2&$A11&B$4,'Bảng giá chi tiết'!$C:$J,8,0),"") | C11: =IFERROR(VLOOKUP($A$2&$A11&C$4,'Bảng giá chi tiết'!$C:$J,8,0),"") | D11: =IFERROR(VLOOKUP($A$2&$A11&D$4,'Bảng giá chi tiết'!$C:$J,8,0),"") | E11: =IFERROR(VLOOKUP($A$2&$A11&E$4,'Bảng giá chi tiết'!$C:$J,8,0),"") | F11: =IFERROR(VLOOKUP($A$2&$A11&F$4,'Bảng giá chi tiết'!$C:$J,8,0),"") | G11: =IFERROR(VLOOKUP($A$2&$A11&G$4,'Bảng giá chi tiết'!$C:$J,8,0),"") | H11: =IFERROR(VLOOKUP($A$2&$A11&H$4,'Bảng giá chi tiết'!$C:$J,8,0),"") | I11: =IFERROR(VLOOKUP($A$2&$A11&I$4,'Bảng giá chi tiết'!$C:$J,8,0),"") | ... T11: =IFERROR(VLOOKUP($A$2&$A11&T$4,'Bảng giá chi tiết'!$C:$J,8,0),"") | U11: 03
A12: 04 | B12: =IFERROR(VLOOKUP($A$2&$A12&B$4,'Bảng giá chi tiết'!$C:$J,8,0),"") | C12: =IFERROR(VLOOKUP($A$2&$A12&C$4,'Bảng giá chi tiết'!$C:$J,8,0),"") | D12: =IFERROR(VLOOKUP($A$2&$A12&D$4,'Bảng giá chi tiết'!$C:$J,8,0),"") | E12: =IFERROR(VLOOKUP($A$2&$A12&E$4,'Bảng giá chi tiết'!$C:$J,8,0),"") | F12: =IFERROR(VLOOKUP($A$2&$A12&F$4,'Bảng giá chi tiết'!$C:$J,8,0),"") | G12: =IFERROR(VLOOKUP($A$2&$A12&G$4,'Bảng giá chi tiết'!$C:$J,8,0),"") | H12: =IFERROR(VLOOKUP($A$2&$A12&H$4,'Bảng giá chi tiết'!$C:$J,8,0),"") | I12: =IFERROR(VLOOKUP($A$2&$A12&I$4,'Bảng giá chi tiết'!$C:$J,8,0),"") | ... T12: =IFERROR(VLOOKUP($A$2&$A12&T$4,'Bảng giá chi tiết'!$C:$J,8,0),"") | U12: 04
A13: 05 | B13: =IFERROR(VLOOKUP($A$2&$A13&B$4,'Bảng giá chi tiết'!$C:$J,8,0),"") | C13: =IFERROR(VLOOKUP($A$2&$A13&C$4,'Bảng giá chi tiết'!$C:$J,8,0),"") | D13: =IFERROR(VLOOKUP($A$2&$A13&D$4,'Bảng giá chi tiết'!$C:$J,8,0),"") | E13: =IFERROR(VLOOKUP($A$2&$A13&E$4,'Bảng giá chi tiết'!$C:$J,8,0),"") | F13: =IFERROR(VLOOKUP($A$2&$A13&F$4,'Bảng giá chi tiết'!$C:$J,8,0),"") | G13: =IFERROR(VLOOKUP($A$2&$A13&G$4,'Bảng giá chi tiết'!$C:$J,8,0),"") | H13: =IFERROR(VLOOKUP($A$2&$A13&H$4,'Bảng giá chi tiết'!$C:$J,8,0),"") | I13: =IFERROR(VLOOKUP($A$2&$A13&I$4,'Bảng giá chi tiết'!$C:$J,8,0),"") | ... T13: =IFERROR(VLOOKUP($A$2&$A13&T$4,'Bảng giá chi tiết'!$C:$J,8,0),"") | U13: 05
A14: 06 | B14: =IFERROR(VLOOKUP($A$2&$A14&B$4,'Bảng giá chi tiết'!$C:$J,8,0),"") | C14: =IFERROR(VLOOKUP($A$2&$A14&C$4,'Bảng giá chi tiết'!$C:$J,8,0),"") | D14: =IFERROR(VLOOKUP($A$2&$A14&D$4,'Bảng giá chi tiết'!$C:$J,8,0),"") | E14: =IFERROR(VLOOKUP($A$2&$A14&E$4,'Bảng giá chi tiết'!$C:$J,8,0),"") | F14: =IFERROR(VLOOKUP($A$2&$A14&F$4,'Bảng giá chi tiết'!$C:$J,8,0),"") | G14: =IFERROR(VLOOKUP($A$2&$A14&G$4,'Bảng giá chi tiết'!$C:$J,8,0),"") | H14: =IFERROR(VLOOKUP($A$2&$A14&H$4,'Bảng giá chi tiết'!$C:$J,8,0),"") | I14: =IFERROR(VLOOKUP($A$2&$A14&I$4,'Bảng giá chi tiết'!$C:$J,8,0),"") | ... T14: =IFERROR(VLOOKUP($A$2&$A14&T$4,'Bảng giá chi tiết'!$C:$J,8,0),"") | U14: 06
A15: 07 | B15: =IFERROR(VLOOKUP($A$2&$A15&B$4,'Bảng giá chi tiết'!$C:$J,8,0),"") | C15: =IFERROR(VLOOKUP($A$2&$A15&C$4,'Bảng giá chi tiết'!$C:$J,8,0),"") | D15: =IFERROR(VLOOKUP($A$2&$A15&D$4,'Bảng giá chi tiết'!$C:$J,8,0),"") | E15: =IFERROR(VLOOKUP($A$2&$A15&E$4,'Bảng giá chi tiết'!$C:$J,8,0),"") | F15: =IFERROR(VLOOKUP($A$2&$A15&F$4,'Bảng giá chi tiết'!$C:$J,8,0),"") | G15: =IFERROR(VLOOKUP($A$2&$A15&G$4,'Bảng giá chi tiết'!$C:$J,8,0),"") | H15: =IFERROR(VLOOKUP($A$2&$A15&H$4,'Bảng giá chi tiết'!$C:$J,8,0),"") | I15: =IFERROR(VLOOKUP($A$2&$A15&I$4,'Bảng giá chi tiết'!$C:$J,8,0),"") | ... T15: =IFERROR(VLOOKUP($A$2&$A15&T$4,'Bảng giá chi tiết'!$C:$J,8,0),"") | U15: 07
A16: 08 | B16: =IFERROR(VLOOKUP($A$2&$A16&B$4,'Bảng giá chi tiết'!$C:$J,8,0),"") | C16: =IFERROR(VLOOKUP($A$2&$A16&C$4,'Bảng giá chi tiết'!$C:$J,8,0),"") | D16: =IFERROR(VLOOKUP($A$2&$A16&D$4,'Bảng giá chi tiết'!$C:$J,8,0),"") | E16: =IFERROR(VLOOKUP($A$2&$A16&E$4,'Bảng giá chi tiết'!$C:$J,8,0),"") | F16: =IFERROR(VLOOKUP($A$2&$A16&F$4,'Bảng giá chi tiết'!$C:$J,8,0),"") | G16: =IFERROR(VLOOKUP($A$2&$A16&G$4,'Bảng giá chi tiết'!$C:$J,8,0),"") | H16: =IFERROR(VLOOKUP($A$2&$A16&H$4,'Bảng giá chi tiết'!$C:$J,8,0),"") | I16: =IFERROR(VLOOKUP($A$2&$A16&I$4,'Bảng giá chi tiết'!$C:$J,8,0),"") | ... T16: =IFERROR(VLOOKUP($A$2&$A16&T$4,'Bảng giá chi tiết'!$C:$J,8,0),"") | U16: 08
A17: 09 | B17: =IFERROR(VLOOKUP($A$2&$A17&B$4,'Bảng giá chi tiết'!$C:$J,8,0),"") | C17: =IFERROR(VLOOKUP($A$2&$A17&C$4,'Bảng giá chi tiết'!$C:$J,8,0),"") | D17: =IFERROR(VLOOKUP($A$2&$A17&D$4,'Bảng giá chi tiết'!$C:$J,8,0),"") | E17: =IFERROR(VLOOKUP($A$2&$A17&E$4,'Bảng giá chi tiết'!$C:$J,8,0),"") | F17: =IFERROR(VLOOKUP($A$2&$A17&F$4,'Bảng giá chi tiết'!$C:$J,8,0),"") | G17: =IFERROR(VLOOKUP($A$2&$A17&G$4,'Bảng giá chi tiết'!$C:$J,8,0),"") | H17: =IFERROR(VLOOKUP($A$2&$A17&H$4,'Bảng giá chi tiết'!$C:$J,8,0),"") | I17: =IFERROR(VLOOKUP($A$2&$A17&I$4,'Bảng giá chi tiết'!$C:$J,8,0),"") | ... T17: =IFERROR(VLOOKUP($A$2&$A17&T$4,'Bảng giá chi tiết'!$C:$J,8,0),"") | U17: 09
A18: 10 | B18: =IFERROR(VLOOKUP($A$2&$A18&B$4,'Bảng giá chi tiết'!$C:$J,8,0),"") | C18: =IFERROR(VLOOKUP($A$2&$A18&C$4,'Bảng giá chi tiết'!$C:$J,8,0),"") | D18: =IFERROR(VLOOKUP($A$2&$A18&D$4,'Bảng giá chi tiết'!$C:$J,8,0),"") | E18: =IFERROR(VLOOKUP($A$2&$A18&E$4,'Bảng giá chi tiết'!$C:$J,8,0),"") | F18: =IFERROR(VLOOKUP($A$2&$A18&F$4,'Bảng giá chi tiết'!$C:$J,8,0),"") | G18: =IFERROR(VLOOKUP($A$2&$A18&G$4,'Bảng giá chi tiết'!$C:$J,8,0),"") | H18: =IFERROR(VLOOKUP($A$2&$A18&H$4,'Bảng giá chi tiết'!$C:$J,8,0),"") | I18: =IFERROR(VLOOKUP($A$2&$A18&I$4,'Bảng giá chi tiết'!$C:$J,8,0),"") | ... T18: =IFERROR(VLOOKUP($A$2&$A18&T$4,'Bảng giá chi tiết'!$C:$J,8,0),"") | U18: 10
A19: 11 | B19: =IFERROR(VLOOKUP($A$2&$A19&B$4,'Bảng giá chi tiết'!$C:$J,8,0),"") | C19: =IFERROR(VLOOKUP($A$2&$A19&C$4,'Bảng giá chi tiết'!$C:$J,8,0),"") | D19: =IFERROR(VLOOKUP($A$2&$A19&D$4,'Bảng giá chi tiết'!$C:$J,8,0),"") | E19: =IFERROR(VLOOKUP($A$2&$A19&E$4,'Bảng giá chi tiết'!$C:$J,8,0),"") | F19: =IFERROR(VLOOKUP($A$2&$A19&F$4,'Bảng giá chi tiết'!$C:$J,8,0),"") | G19: =IFERROR(VLOOKUP($A$2&$A19&G$4,'Bảng giá chi tiết'!$C:$J,8,0),"") | H19: =IFERROR(VLOOKUP($A$2&$A19&H$4,'Bảng giá chi tiết'!$C:$J,8,0),"") | I19: =IFERROR(VLOOKUP($A$2&$A19&I$4,'Bảng giá chi tiết'!$C:$J,8,0),"") | ... T19: =IFERROR(VLOOKUP($A$2&$A19&T$4,'Bảng giá chi tiết'!$C:$J,8,0),"") | U19: 11
